Workbook

Sheet Start Here
A1: Fleet Booking and Dispatch Portal - Test run with three users
A3: What this is | B3: A step-by-step test of the five deployed web parts using only three logins: Aliakbar (requester and Coordinator), Aabid and Mahedi (drivers). Where a test needs a situation your data does not have, the step tells you exactly which master-list value to change first and what to put back afterwards.
A4: The three people | B4: ALIAKBAR: books rides (Book a Ride, My Bookings) and runs dispatch (Dispatch Dashboard, Fleet Reports). Must not be linked to any DriversMaster row. AABID: driver 'Queinfotech aabid', item ID 18, home Yas Island Resort, also linked to Al Maryah Tower, cap 1, Patrol / Pathfinder / Kicks / Creta. MAHEDI: driver 'Queinfotech mahedi', item ID 19, home Al Maryah Tower, cap 2, Kicks / Creta / Patrol. Keep all three signed in at once in separate browsers or profiles.
A5: Sheets, in order | B5: 0 Setup - once, to reach the baseline. 1 Book a Ride. 2 Booking results - who is offered what, driven by master-data changes. 3 My Bookings. 4 Driver Dashboard. 5 Dispatch Dashboard. 6 Fleet Reports - last. 7 Full journeys - whole stories with all three people, permissions, look and feel.
A6: Columns | B6: 'Set up first (data and state)' (blue): what must be true before the step, including any master-list edit. 'Baseline' means the state on the Baseline data sheet. 'Put back afterwards' (blue): undo your edits here before the next step. Yellow columns are yours to fill in: Actual result, Status, Notes / Bug ID, Tested by, Date tested.
A7: The standard booking | B7: Pickup Head Office, destination Reem Island Office, Today, a slot within the next 4 hours, Staff, Patrol, 2 passengers. In the baseline this is offered to both drivers and uses vehicle AUH-11223.
A8: Status values | B8: Not Run (default), Pass, Fail, Blocked, N/A. The Progress sheet counts them.
A9: No flows | B9: The pack assumes no Power Automate flow is running. Three things therefore never happen by themselves, and steps tell you to do them by hand: an unanswered request does not move to the Coordinator; after Complete the request stays Allocated and the driver and vehicle stay On Trip; a Held booking is not released.
A10: Reset between steps | B10: If things get tangled: 1) cancel every pending request from Dispatch; 2) in TripAssignments set any Assigned, En Route or In Transit trip to Cancelled; 3) set both drivers' Status and both vehicles' VehStatus to Available; 4) compare the masters with the Baseline data sheet.
A11: Keep open | B11: The lists TransportRequests, RideOffers, TripAssignments, TripStatusHistory, DriversMaster, VehicleMaster, DLClientMaster, AvailabilityBlocks, AllocationRules. The browser console in Aliakbar's session: the engine explains each decision in lines starting [FleetPortal].
A12: Timing | B12: Driver page refreshes every 20 s, My Bookings 30 s, Dispatch 60 s, the booking wizard 10 s. Master-data edits take effect on the next booking; reload a page after changing a driver's own record.
A13: Example of a filled row | B13: Actual result: 'Offer created for Mahedi only; console showed Aabid not qualified.' Status: Pass Tested by: MAS Date tested: 12-Oct-2026

Sheet Progress
A1: Progress
A2: Counts update as you set Status on each sheet.
A4: Sheet | B4: Total | C4: Pass | D4: Fail | E4: Blocked | F4: N/A | G4: Not Run | H4: % run | I4: % passed of run
A5: 0 Setup | B5: =COUNTA('0 Setup'!$K$5:$K$18) -> 14 | C5: =COUNTIF('0 Setup'!$K$5:$K$18,"Pass") -> 0 | D5: =COUNTIF('0 Setup'!$K$5:$K$18,"Fail") -> 0 | E5: =COUNTIF('0 Setup'!$K$5:$K$18,"Blocked") -> 0 | F5: =COUNTIF('0 Setup'!$K$5:$K$18,"N/A") -> 0 | G5: =COUNTIF('0 Setup'!$K$5:$K$18,"Not Run") -> 14 | H5: =IF(B5=0,0,(B5-G5)/B5) -> 0 | I5: =IF((C5+D5)=0,0,C5/(C5+D5)) -> 0
A6: 1 Book a Ride | B6: =COUNTA('1 Book a Ride'!$K$5:$K$38) -> 34 | C6: =COUNTIF('1 Book a Ride'!$K$5:$K$38,"Pass") -> 34 | D6: =COUNTIF('1 Book a Ride'!$K$5:$K$38,"Fail") -> 0 | E6: =COUNTIF('1 Book a Ride'!$K$5:$K$38,"Blocked") -> 0 | F6: =COUNTIF('1 Book a Ride'!$K$5:$K$38,"N/A") -> 0 | G6: =COUNTIF('1 Book a Ride'!$K$5:$K$38,"Not Run") -> 0 | H6: =IF(B6=0,0,(B6-G6)/B6) -> 1 | I6: =IF((C6+D6)=0,0,C6/(C6+D6)) -> 1
A7: 2 Booking results | B7: =COUNTA('2 Booking results'!$K$5:$K$33) -> 29 | C7: =COUNTIF('2 Booking results'!$K$5:$K$33,"Pass") -> 0 | D7: =COUNTIF('2 Booking results'!$K$5:$K$33,"Fail") -> 0 | E7: =COUNTIF('2 Booking results'!$K$5:$K$33,"Blocked") -> 0 | F7: =COUNTIF('2 Booking results'!$K$5:$K$33,"N/A") -> 0 | G7: =COUNTIF('2 Booking results'!$K$5:$K$33,"Not Run") -> 29 | H7: =IF(B7=0,0,(B7-G7)/B7) -> 0 | I7: =IF((C7+D7)=0,0,C7/(C7+D7)) -> 0
A8: 3 My Bookings | B8: =COUNTA('3 My Bookings'!$K$5:$K$20) -> 16 | C8: =COUNTIF('3 My Bookings'!$K$5:$K$20,"Pass") -> 0 | D8: =COUNTIF('3 My Bookings'!$K$5:$K$20,"Fail") -> 0 | E8: =COUNTIF('3 My Bookings'!$K$5:$K$20,"Blocked") -> 0 | F8: =COUNTIF('3 My Bookings'!$K$5:$K$20,"N/A") -> 0 | G8: =COUNTIF('3 My Bookings'!$K$5:$K$20,"Not Run") -> 16 | H8: =IF(B8=0,0,(B8-G8)/B8) -> 0 | I8: =IF((C8+D8)=0,0,C8/(C8+D8)) -> 0
A9: 4 Driver Dashboard | B9: =COUNTA('4 Driver Dashboard'!$K$5:$K$38) -> 34 | C9: =COUNTIF('4 Driver Dashboard'!$K$5:$K$38,"Pass") -> 0 | D9: =COUNTIF('4 Driver Dashboard'!$K$5:$K$38,"Fail") -> 0 | E9: =COUNTIF('4 Driver Dashboard'!$K$5:$K$38,"Blocked") -> 0 | F9: =COUNTIF('4 Driver Dashboard'!$K$5:$K$38,"N/A") -> 0 | G9: =COUNTIF('4 Driver Dashboard'!$K$5:$K$38,"Not Run") -> 34 | H9: =IF(B9=0,0,(B9-G9)/B9) -> 0 | I9: =IF((C9+D9)=0,0,C9/(C9+D9)) -> 0
A10: 5 Dispatch Dashboard | B10: =COUNTA('5 Dispatch Dashboard'!$K$5:$K$39) -> 35 | C10: =COUNTIF('5 Dispatch Dashboard'!$K$5:$K$39,"Pass") -> 0 | D10: =COUNTIF('5 Dispatch Dashboard'!$K$5:$K$39,"Fail") -> 0 | E10: =COUNTIF('5 Dispatch Dashboard'!$K$5:$K$39,"Blocked") -> 0 | F10: =COUNTIF('5 Dispatch Dashboard'!$K$5:$K$39,"N/A") -> 0 | G10: =COUNTIF('5 Dispatch Dashboard'!$K$5:$K$39,"Not Run") -> 35 | H10: =IF(B10=0,0,(B10-G10)/B10) -> 0 | I10: =IF((C10+D10)=0,0,C10/(C10+D10)) -> 0
A11: 6 Fleet Reports | B11: =COUNTA('6 Fleet Reports'!$K$5:$K$22) -> 18 | C11: =COUNTIF('6 Fleet Reports'!$K$5:$K$22,"Pass") -> 0 | D11: =COUNTIF('6 Fleet Reports'!$K$5:$K$22,"Fail") -> 0 | E11: =COUNTIF('6 Fleet Reports'!$K$5:$K$22,"Blocked") -> 0 | F11: =COUNTIF('6 Fleet Reports'!$K$5:$K$22,"N/A") -> 0 | G11: =COUNTIF('6 Fleet Reports'!$K$5:$K$22,"Not Run") -> 18 | H11: =IF(B11=0,0,(B11-G11)/B11) -> 0 | I11: =IF((C11+D11)=0,0,C11/(C11+D11)) -> 0
A12: 7 Full journeys | B12: =COUNTA('7 Full journeys'!$K$5:$K$25) -> 21 | C12: =COUNTIF('7 Full journeys'!$K$5:$K$25,"Pass") -> 0 | D12: =COUNTIF('7 Full journeys'!$K$5:$K$25,"Fail") -> 0 | E12: =COUNTIF('7 Full journeys'!$K$5:$K$25,"Blocked") -> 0 | F12: =COUNTIF('7 Full journeys'!$K$5:$K$25,"N/A") -> 0 | G12: =COUNTIF('7 Full journeys'!$K$5:$K$25,"Not Run") -> 21 | H12: =IF(B12=0,0,(B12-G12)/B12) -> 0 | I12: =IF((C12+D12)=0,0,C12/(C12+D12)) -> 0
A13: All sheets | B13: =SUM(B5:B12) -> 201 | C13: =SUM(C5:C12) -> 34 | D13: =SUM(D5:D12) -> 0 | E13: =SUM(E5:E12) -> 0 | F13: =SUM(F5:F12) -> 0 | G13: =SUM(G5:G12) -> 167 | H13: =IF(B13=0,0,(B13-G13)/B13) -> 0.16915423 | I13: =IF((C13+D13)=0,0,C13/(C13+D13)) -> 1

Sheet Baseline data
A1: The state the master lists should be in before each step, unless the step says otherwise. Source: the data you sent on 9 Oct 2026.
A3: DriversMaster
A4: Title (driver name) | B4: DriverID / item ID | C4: Home property | D4: QualifiedVehicleTypes | E4: Status | F4: MaxConcurrentTrips | G4: LicenceExpiry | H4: Other
A5: Queinfotech aabid | B5: D001 / 18 | C5: Yas Island Resort | D5: Patrol; Pathfinder; Kicks / Creta | E5: Available | F5: 1 | G5: 14 Aug 2029 | H5: IsActive Yes. UserAccount = Aabid's login. Phone +971 50 123 4567
A6: Queinfotech mahedi | B6: D002 / 19 | C6: Al Maryah Tower | D6: Kicks / Creta; Patrol | E6: Available | F6: 2 | G6: 02 Feb 2029 | H6: IsActive Yes. UserAccount = Mahedi's login. Phone +971 50 123 4568
A7: Any other driver row | B7: - | C7: - | D7: - | E7: - | F7: - | G7: - | H7: IsActive No and UserAccount empty (or delete the row)
A9: DLClientMaster (required for this pack - set in step S-04)
A10: DriverID | B10: PropertyRef
A11: Queinfotech aabid | B11: Yas Island Resort
A12: Queinfotech aabid | B12: Al Maryah Tower
A13: Queinfotech mahedi | B13: Al Maryah Tower
A15: VehicleMaster
A16: Plate | B16: VehicleType | C16: Vehicle | D16: PropertyRef | E16: DefaultDriver | F16: VehStatus | G16: Capacity | H16: Other
A17: AUH-11223 | B17: Patrol | C17: White Nissan Patrol | D17: Al Maryah Tower | E17: Queinfotech mahedi | F17: Available | G17: 7 | H17: The vehicle nearly every step uses
A18: AUH-01234 | B18: Cargo Van | C18: Blue Ford Transit | D18: Khalifa Industrial Park | E18: Queinfotech aabid | F18: Available | G18: 2 | H18: Borrowed as a second Patrol in a few steps; always put it back
A19: Any other vehicle | B19: - | C19: - | D19: - | E19: - | F19: - | G19: - | H19: No other Patrol at Al Maryah Tower
A21: Other lists
A22: List | B22: Baseline
A23: AvailabilityBlocks | B23: No row covering today for either driver or vehicle
A24: TripAssignments | B24: No trip in Assigned, En Route or In Transit
A25: TransportRequests | B25: Nothing in Submitted, Broadcasting or Awaiting Coordinator
A26: AllocationRules | B26: 9 rules. Offer window 15 min, cap 1, advance release 4 h, Automatic; 'Khalifa Industrial Park - Client or Client Guest' is Manual
A27: Locations | B27: 12 active. Al Maryah Tower: Head Office, Reem Island Office, Central Warehouse. Yas Island Resort: Yas Mall, Yas Resort Reception, Yas Staff Accommodation. Khalifa Industrial Park: Khalifa Plant Gate 2, Khalifa Admin Block. No property: both airports, Cleveland Clinic Abu Dhabi, Downtown Abu Dhabi
A28: VehicleTypes | B28: Staff: Patrol, Kicks / Creta, Others. Client: Patrol, Pathfinder, Kicks / Creta, Others. Items: four vans, Others
A30: Groups
A31: Login | B31: Groups
A32: Aliakbar | B32: FM Requesters, FM Coordinators, FM Admins. Not FM Drivers
A33: Aabid | B33: FM Drivers
A34: Mahedi | B34: FM Drivers
A36: Data changes used in this pack
A37: To make this happen | B37: Change | C37: Used in
A38: Only one driver offered | B38: Remove Patrol from the other's QualifiedVehicleTypes; or delete their DLClientMaster row for Al Maryah Tower; or IsActive = No; or LicenceExpiry = today; or a Leave row in AvailabilityBlocks | C38: Sheet 2
A39: Immediate escalation | B39: AUH-11223 VehStatus = Under Maintenance | C39: Sheets 1, 2, 3, 7
A40: A second Patrol | B40: AUH-01234: VehicleType = Patrol, PropertyRef = Al Maryah Tower | C40: Sheets 2, 4, 5, 7
A41: Fast offer expiry | B41: 'Al Maryah Tower - Staff' rule: OfferWindowMinutes = 2 | C41: Sheets 2, 4
A42: No broadcast at all | B42: 'Al Maryah Tower - Staff' rule: Mode = Manual | C42: Sheet 2
A43: Release a Held booking | B43: TransportRequests row: ReqStatus = Submitted, then open Dispatch | C43: Sheets 2, 7
A44: Imitate offer expiry | B44: TransportRequests row: ReqStatus = Awaiting Coordinator | C44: Sheet 5
A45: Free a driver and vehicle after Complete | B45: Driver Status = Available; vehicle VehStatus = Available | C45: Sheets 4, 5, 7

Sheet 0 Setup
A1: Setup
A2: Get the three logins, the master data and the pages into a known state. Do every step once, in order.
A4: Step | B4: ID | C4: Feature | D4: Sign in as | E4: Priority | F4: Set up first (data and state) | G4: Test steps | H4: Expected result | I4: Put back afterwards | J4: Actual result | K4: Status | L4: Notes / Bug ID | M4: Tested by | N4: Date tested
A5: 1 | B5: S-01 | C5: Three sessions | D5: - | E5: High | F5: - | G5: 1. Open three separate browser sessions so all three people can be signed in at once: for example Edge for Aliakbar, Chrome for Aabid, and a private window or another browser profile for Mahedi. 2. Sign each one in to the site. | H5: Three sessions, one per login, side by side. Most driver tests need you to watch two screens at once. | I5: - | K5: Not Run
A6: 2 | B6: S-02 | C6: Groups | D6: Site owner | E6: High | F6: - | G6: 1. Open Site permissions and check group membership. | H6: - Aliakbar: FM Requesters, FM Coordinators and FM Admins. NOT in FM Drivers. - Aabid and Mahedi: FM Drivers. - Record anything different in Notes. | I6: - | K6: Not Run
A7: 3 | B7: S-03 | C7: DriversMaster | D7: Site owner | E7: High | F7: - | G7: 1. Open DriversMaster and compare with the 'Baseline data' sheet. 2. For any other driver row still in the list (Mohammed Iqbal, Jomon Varghese, Ali Hassan, Arun Prasad from the earlier data): set IsActive = No and clear UserAccount, or delete the row. | H7: - Two active drivers only: 'Queinfotech aabid' (item ID 18, cap 1, home property Yas Island Resort) and 'Queinfotech mahedi' (item ID 19, cap 2, home property Al Maryah Tower), both Status Available, each with their own login in UserAccount. - Aliakbar's login is not in UserAccount on any row. If it is, Aliakbar is treated as a driver and the Dispatch page is narrowed to that driver's property. | I7: - | K7: Not Run
A8: 4 | B8: S-04 | C8: DLClientMaster | D8: Site owner | E8: High | F8: - | G8: 1. Open DLClientMaster. 2. Make sure these three rows exist, and no others, for the two drivers: Queinfotech aabid → Yas Island Resort; Queinfotech aabid → Al Maryah Tower; Queinfotech mahedi → Al Maryah Tower. | H8: - Aabid is linked to two properties: his home, Yas Island Resort, and Al Maryah Tower. Mahedi is linked to Al Maryah Tower only. - The Al Maryah Tower link for Aabid is what lets one booking reach both drivers; the only Patrol is based there. The offer list is built from these links. The HomeProperty column on DriversMaster plays no part in it. - Record the rows you actually have. | I8: - | K8: Not Run
A9: 5 | B9: S-05 | C9: VehicleMaster | D9: Site owner | E9: High | F9: - | G9: 1. Open VehicleMaster and compare with the 'Baseline data' sheet. 2. Write in Notes every other vehicle still in the list, with its type and property. | H9: - AUH-11223: Patrol, White Nissan Patrol, Al Maryah Tower, Available, default driver Queinfotech mahedi. - AUH-01234: Cargo Van, Blue Ford Transit, Khalifa Industrial Park, Available, default driver Queinfotech aabid. - No other Patrol is based at Al Maryah Tower. (If one is, set its VehStatus to Under Maintenance for the duration of testing.) | I9: - | K9: Not Run
A10: 6 | B10: S-06 | C10: AvailabilityBlocks | D10: Site owner | E10: High | F10: - | G10: 1. Open AvailabilityBlocks. | H10: No row for either driver or either vehicle that covers today. Delete or shorten any that do. | I10: - | K10: Not Run
A11: 7 | B11: S-07 | C11: Open trips | D11: Site owner | E11: High | F11: - | G11: 1. Open TripAssignments and filter TripStatus to Assigned, En Route, In Transit. | H11: No open trips. If any exist, set their TripStatus to Cancelled by hand. An open trip holds its driver and vehicle and changes every result below. | I11: - | K11: Not Run
A12: 8 | B12: S-08 | C12: List permissions | D12: Site owner | E12: High | F12: - | G12: 1. Check what each group can do on the lists. | H12: - FM Drivers: Contribute on TransportRequests, RideOffers, TripAssignments, TripStatusHistory, DriversMaster, VehicleMaster. Accepting a trip writes to all six as the driver. - FM Requesters: add and edit on TransportRequests, RideOffers and TripStatusHistory, and read on DriversMaster, VehicleMaster, DLClientMaster, AvailabilityBlocks, TripAssignments, AllocationRules, Locations, VehicleTypes. The offers are created in the requester's browser. - Record what is actually set. | I12: - | K12: Not Run
A13: 9 | B13: S-09 | C13: Pages load | D13: ALIAKBAR | E13: High | F13: Console open (F12). | G13: 1. Open Book a Ride, My Bookings, Dispatch Dashboard and Fleet Reports. 2. Press Ctrl+F5 on each. | H13: All four show their heading and content with no red banner and no red console errors. The five .js bundles load with status 200. | I13: - | K13: Not Run
A14: 10 | B14: S-10 | C14: Aliakbar is not a driver | D14: ALIAKBAR | E14: High | F14: - | G14: 1. Open the Driver Dashboard page. | H14: 'You are not set up as a driver', with the explanation that the account is not linked to a DriversMaster record. | I14: - | K14: Not Run
A15: 11 | B15: S-11 | C15: Driver pages load | D15: AABID + MAHEDI | E15: High | F15: - | G15: 1. Each driver opens the Driver Dashboard. | H15: - Aabid: caption 'Signed in as Queinfotech aabid. Offers refresh automatically.' - Mahedi: 'Signed in as Queinfotech mahedi...'. - Both: buttons 'Sound: off' and 'Refresh now'; 'No open offers'; 'No trips assigned to you right now'; no red banner. | I15: - | K15: Not Run
A16: 12 | B16: S-12 | C16: Clear the old requests | D16: ALIAKBAR | E16: High | F16: FB-0020 and FB-0021 (booked by Noreply Myhub) are still Broadcasting from last week. | G16: 1. Open Dispatch and find them in Pending requests. 2. Click Cancel on FB-0021, type 'test clean-up', confirm. 3. Do the same for FB-0020. | H16: - Each leaves the grid; ReqStatus becomes Cancelled with the reason; any Pending offers become Withdrawn. - FB-0020 still points to trip TR-0003. If a red banner appears while cancelling it, check whether TR-0003 still exists in TripAssignments and record what you find. - Pending requests now reads 0. | I16: - | K16: Not Run
... A18: 14 | B18: S-14 | C18: Smoke test of the whole chain | D18: ALIAKBAR + drivers | E18: High | F18: Baseline. All three sessions open; both drivers on the Driver Dashboard. | G18: 1. Aliakbar books the standard booking (see Start Here). 2. Watch both driver screens for 20 seconds. 3. Aliakbar opens Dispatch and Cancels the request with 'smoke test'. 4. Watch both driver screens for 20 seconds. | H18: - Aliakbar sees 'Your request has been received' with a reference (FB-0022 or higher). - Both drivers get a banner '1 open ride offer waiting for you' and a card with a countdown near 15 minutes. - After the cancel both cards disappear. In RideOffers both offers read Withdrawn. - If this works, booking, allocation, the driver page and Dispatch are all wired up correctly. | I18: - | K18: Not Run

Sheet 1 Book a Ride
A1: Book a Ride
A2: The booking wizard, screen by screen. Sign in as Aliakbar unless the step says otherwise.
A4: Step | B4: ID | C4: Feature | D4: Sign in as | E4: Priority | F4: Set up first (data and state) | G4: Test steps | H4: Expected result | I4: Put back afterwards | J4: Actual result | K4: Status | L4: Notes / Bug ID | M4: Tested by | N4: Date tested
A5: 1 | B5: B-01 | C5: Load | D5: ALIAKBAR | E5: High | F5: - | G5: 1. Open Book a Ride. | H5: - Heading 'Book a ride', caption 'Four steps. Everything is a choice from a list, so nothing can be mistyped.' - Steps Where, When, Request type, Vehicle. Back disabled. Button 'Continue'. No pickup pre-selected (Aliakbar has no home property). | I5: - | J5: Same as Expected | K5: Pass | M5: Aabid | N5: 46275
A6: 2 | B6: B-02 | C6: Step 1 - list | D6: ALIAKBAR | E6: High | F6: - | G6: 1. Click in Destination with nothing typed. | H6: 12 locations with their addresses. 'Old Depot (closed)' is not listed (inactive). | I6: - | J6: Same as Expected | K6: Pass | M6: Aabid | N6: 46275
A7: 3 | B7: B-03 | C7: Step 1 - search | D7: ALIAKBAR | E7: High | F7: - | G7: 1. Type: yas 2. Clear; type: mussafah 3. Clear; type: airport | H7: - yas: Yas Mall, Yas Resort Reception, Yas Staff Accommodation. - mussafah: Central Warehouse only (matched on address). - airport: Zayed International Airport T1 and T3. | I7: - | J7: Same as Expected | K7: Pass | M7: Aabid | N7: 46275
A8: 4 | B8: B-04 | C8: Step 1 - typed text is never the answer | D8: ALIAKBAR | E8: High | F8: - | G8: 1. Type: zzzz 2. Click Continue without choosing anything. | H8: 'No location matches that. Try a shorter search.' Continue is refused with 'Choose a pickup point.' | I8: - | J8: Same as Expected | K8: Pass | M8: Aabid | N8: 46275
A9: 5 | B9: B-05 | C9: Step 1 - validation | D9: ALIAKBAR | E9: Medium | F9: - | G9: 1. Choose Head Office for pickup only; Continue. 2. Choose Head Office for destination too; Continue. | H9: 'Choose a destination.' then 'The pickup point and the destination are the same.' | I9: - | J9: Same as Expected | K9: Pass | M9: Aabid | N9: 46275
A10: 6 | B10: B-06 | C10: Step 1 - cross property | D10: ALIAKBAR | E10: Medium | F10: - | G10: 1. Pickup Head Office, destination Yas Mall; Continue. | H10: Accepted. The trip belongs to the pickup's property. | I10: - | J10: Same as Expected | K10: Pass | M10: Aabid | N10: 46275
A11: 7 | B11: B-07 | C11: Step 2 - slots | D11: ALIAKBAR | E11: High | F11: Step 1 done. | G11: 1. Read the slot grid for Today. | H11: 48 slots, 30 minutes apart, 24-hour Gulf time. Every slot earlier than now + 15 minutes is disabled. | I11: - | J11: Same as Expected | K11: Pass | M11: Aabid | N11: 46275
A12: 8 | B12: B-08 | C12: Step 2 - validation | D12: ALIAKBAR | E12: High | F12: - | G12: 1. Click Continue with no slot chosen. | H12: 'Choose a time.' | I12: - | J12: Same as Expected | K12: Pass | M12: Aabid | N12: 46275
A13: 9 | B13: B-09 | C13: Step 2 - another day | D13: ALIAKBAR | E13: High | F13: - | G13: 1. Click 'Another day'; pick tomorrow. 2. Pick yesterday. | H13: Tomorrow: a Date field appears and all 48 slots are enabled. Yesterday: every slot is disabled. | I13: - | J13: Same as Expected | K13: Pass | M13: Aabid | N13: 46275
A14: 10 | B14: B-10 | C14: Step 2 - toggle clears the slot | D14: ALIAKBAR | E14: Medium | F14: - | G14: 1. Choose a slot. 2. Click 'Another day', then 'Today'. 3. Continue. | H14: The slot is cleared; 'Choose a time.' | I14: - | J14: Same as Expected | K14: Pass | M14: Aabid | N14: 46275
A15: 11 | B15: B-11 | C15: Step 2 - time zone | D15: ALIAKBAR | E15: Medium | F15: Set the PC time zone to India or UTC. | G15: 1. Reload; go to step 2. | H15: Slot labels and the cut-off are still Gulf time. | I15: PC time zone. | J15: Same as Expected | K15: Pass | M15: Aabid | N15: 46275
A16: 12 | B16: B-12 | C16: Step 3 - tiles | D16: ALIAKBAR | E16: High | F16: Step 2 done. | G16: 1. Read the tiles. 2. Continue without choosing. | H16: Client or Client Guest, Staff, Items or Documents, each with a caption. 'Choose a request type.' | I16: - | J16: Same as Expected | K16: Pass | M16: Aabid | N16: 46275
... A38: 34 | B38: B-34 | C38: Failure | D38: ALIAKBAR | E38: Medium | F38: On step 4, all filled in. | G38: 1. Set the browser Offline in DevTools; Submit; go back online. | H38: Red banner saying the change could not be saved and nothing was saved. The form stays filled in. | I38: - | J38: Same as Expected | K38: Pass | M38: Aabid | N38: 46275

Sheet 2 Booking results
A1: Booking results
A2: What the engine does after Submit. Change the master data as the step says, book as Aliakbar, check RideOffers and the browser console, then put the data back.
A4: Step | B4: ID | C4: Feature | D4: Sign in as | E4: Priority | F4: Set up first (data and state) | G4: Test steps | H4: Expected result | I4: Put back afterwards | J4: Actual result | K4: Status | L4: Notes / Bug ID | M4: Tested by | N4: Date tested
A5: 1 | B5: A-01 | C5: Both drivers offered | D5: ALIAKBAR | E5: High | F5: Baseline. | G5: 1. Open the console. 2. Book the standard booking. 3. Open the request row and RideOffers. | H5: - ReqStatus Broadcasting. OfferClosesAt = submit time + 15 minutes. - Two Pending offers: FB-00nn-D018 (Queinfotech aabid) and FB-00nn-D019 (Queinfotech mahedi). Vehicle column empty; the vehicle is bound when someone accepts. | I5: Cancel from Dispatch. | K5: Not Run
A6: 2 | B6: A-02 | C6: Not qualified | D6: ALIAKBAR | E6: High | F6: Aabid: remove Patrol from QualifiedVehicleTypes. | G6: 1. Book the standard booking. | H6: One offer only, for Queinfotech mahedi. | I6: Put Patrol back on Aabid. Cancel the request. | K6: Not Run
A7: 3 | B7: A-03 | C7: Nobody qualified | D7: ALIAKBAR | E7: High | F7: Remove Patrol from both drivers' QualifiedVehicleTypes. | G7: 1. Book the standard booking. 2. Read the console. | H7: - Awaiting Coordinator at once; OfferClosesAt = submit time; no offers. - Console: '[FleetPortal] FB-00nn escalated to the Coordinator' with a line per driver ending 'not qualified for the requested vehicle type'. | I7: Put Patrol back on both. Cancel the request. | K7: Not Run
A8: 4 | B8: A-04 | C8: No qualifications at all | D8: ALIAKBAR | E8: Low | F8: Aabid: clear QualifiedVehicleTypes completely. Mahedi: remove Patrol. | G8: 1. Book the standard booking; read the console. | H8: Escalates. Aabid's console line reads 'QualifiedVehicleTypes is empty'. | I8: Restore both drivers' qualifications. Cancel the request. | K8: Not Run
A9: 5 | B9: A-05 | C9: Not linked to the property | D9: ALIAKBAR | E9: High | F9: Delete Aabid's DLClientMaster row for Al Maryah Tower (keep his Yas Island Resort row). | G9: 1. Book the standard booking; read RideOffers. | H9: Offer for Mahedi only. Aabid is no longer allocated to Al Maryah Tower, so he is not offered trips that start there. | I9: Re-create Aabid's link to Al Maryah Tower. Cancel the request. | K9: Not Run
A10: 6 | B10: A-06 | C10: On leave - with a Leave block | D10: ALIAKBAR | E10: High | F10: AvailabilityBlocks: add a row, Driver = Queinfotech aabid, BlockType Leave, from yesterday to next week. | G10: 1. Book the standard booking. | H10: Offer for Mahedi only. | I10: Delete the block. Cancel the request. | K10: Not Run
A11: 7 | B11: A-07 | C11: On leave - Status only | D11: ALIAKBAR | E11: High | F11: Aabid: set Status = On Leave. No AvailabilityBlocks row. | G11: 1. Book the standard booking; read RideOffers. | H11: A driver on leave must not be offered work, so only Mahedi should get an offer. Record whether Aabid is offered it too. | I11: Aabid Status back to Available. Cancel the request. | K11: Not Run
A12: 8 | B12: A-08 | C12: Shift block does not exclude | D12: ALIAKBAR | E12: Low | F12: AvailabilityBlocks: add a row for Mahedi, BlockType Shift, covering today. | G12: 1. Book the standard booking. | H12: Both drivers are offered it. | I12: Delete the block. Cancel the request. | K12: Not Run
A13: 9 | B13: A-09 | C13: Inactive driver | D13: ALIAKBAR | E13: Medium | F13: Mahedi: IsActive = No. | G13: 1. Book the standard booking. 2. Mahedi reloads the Driver Dashboard. | H13: Offer for Aabid only. | I13: Mahedi IsActive = Yes. Cancel the request. | K13: Not Run
A14: 10 | B14: A-10 | C14: Status Inactive | D14: ALIAKBAR | E14: Low | F14: Mahedi: Status = Inactive (IsActive still Yes). | G14: 1. Book the standard booking. | H14: Offer for Aabid only. | I14: Mahedi Status = Available. Cancel the request. | K14: Not Run
A15: 11 | B15: A-11 | C15: Licence expired | D15: ALIAKBAR | E15: High | F15: Aabid: LicenceExpiry = today's date. | G15: 1. Book the standard booking. | H15: Offer for Mahedi only. The licence must be valid to the END of the trip (required time + 2 hours). | I15: Aabid LicenceExpiry back to 14 Aug 2029. Cancel the request. | K15: Not Run
A16: 12 | B16: A-12 | C16: Vehicle under maintenance | D16: ALIAKBAR | E16: High | F16: AUH-11223: VehStatus = Under Maintenance. | G16: 1. Book the standard booking; read the console. | H16: Awaiting Coordinator, no offers. Console: 'vehicles of this type at this property: 0, free: 0' and both drivers 'ELIGIBLE'. Drivers were available; the vehicle was not. | I16: AUH-11223 back to Available. Cancel the request. | K16: Not Run
... A33: 29 | B33: A-29 | C33: Home property is not a link | D33: ALIAKBAR | E33: High | F33: - DLClientMaster: delete Aabid's row for Yas Island Resort (his HomeProperty on DriversMaster stays Yas Island Resort). - AUH-11223: PropertyRef = Yas Island Resort. | G33: 1. Open the console. 2. Book: pickup Yas Resort Reception, destination Yas Mall, today, Staff, Patrol. 3. Read the console. | H33: - Awaiting Coordinator, no offers, although the vehicle is at Yas and Yas is Aabid's home property. - Console: 'DLClientMaster rows for this property: 0' and both drivers 'not allocated to this property in DLClientMaster'. - Changing a driver's HomeProperty alone never changes who is offered a trip; the DLClientMaster row must change too. | I33: Re-create Aabid's Yas Island Resort link. AUH-11223 back to Al Maryah Tower. Cancel the request. | K33: Not Run

Sheet 3 My Bookings
A1: My Bookings
A2: The requester's page. Sign in as Aliakbar.
A4: Step | B4: ID | C4: Feature | D4: Sign in as | E4: Priority | F4: Set up first (data and state) | G4: Test steps | H4: Expected result | I4: Put back afterwards | J4: Actual result | K4: Status | L4: Notes / Bug ID | M4: Tested by | N4: Date tested
A5: 1 | B5: M-01 | C5: Load | D5: ALIAKBAR | E5: High | F5: Aliakbar has several bookings from the earlier sheets. | G5: 1. Open My Bookings. | H5: - Heading 'My bookings', a Refresh button, grid columns Reference, Required, From and to, Request type, Status, Actions. - Newest first; the newest is selected automatically and its button reads 'Showing'. - Every status is a badge with its word. | I5: - | K5: Not Run
A6: 2 | B6: M-02 | C6: Only my own | D6: ALIAKBAR + AABID | E6: High | F6: Aabid has booked at least one ride (B-33). | G6: 1. Aliakbar opens My Bookings. 2. Aabid opens My Bookings. | H6: Each sees only their own requests. Noreply Myhub's FB-0019 to FB-0021 appear for neither. | I6: - | K6: Not Run
A7: 3 | B7: M-03 | C7: Filter | D7: ALIAKBAR | E7: Medium | F7: - | G7: 1. Click the Status header; tick Cancelled; Close. 2. Open it again; Clear. 3. Filter Request type to Staff. | H7: Only Cancelled rows; header shows '▼ filtered (1)'. Clear restores all. Staff shows only Staff rows. | I7: - | K7: Not Run
A8: 4 | B8: M-04 | C8: Detail - Broadcasting | D8: ALIAKBAR | E8: High | F8: Book the standard booking; nobody accepts. | G8: 1. Select it in My Bookings. | H8: Required, From Head Office, To Reem Island Office, Staff, Patrol, Passengers 2. Notice 'We have your request and are finding you a driver...'. No driver or vehicle details. | I8: - | K8: Not Run
A9: 5 | B9: M-05 | C9: Cancel while Broadcasting | D9: ALIAKBAR | E9: High | F9: The Broadcasting request from the previous step. | G9: 1. Note the button label. 2. Click it, type a reason, confirm. 3. Check the row, its offers and both driver screens. | H9: A request no driver has taken should be cancellable. Record the button label, the message shown, and whether anything changed in any list. | I9: Cancel it from Dispatch. | K9: Not Run
A10: 6 | B10: M-06 | C10: Detail - Allocated | D10: ALIAKBAR + AABID | E10: High | F10: Book the standard booking; Aabid accepts. | G10: 1. Select it. | H10: - Badge Allocated. 'Your driver and vehicle': Queinfotech aabid, +971 50 123 4567 (link), White Nissan Patrol, plate AUH-11223. - Progress: Booking confirmed = Now, the other three To come. | I10: Keep the trip for the next steps. | K10: Not Run
A11: 7 | B11: M-07 | C11: Ask to cancel | D11: ALIAKBAR | E11: High | F11: The Allocated request above. | G11: 1. Read the button. 2. Click it; read the dialog; type a reason; click 'Send the request'. 3. Check the request, the trip and TripStatusHistory. | H11: - Button 'Ask to cancel'. Dialog 'Ask the Coordinator to cancel?' says only the Coordinator can cancel now. - Notice: 'A driver has already accepted this trip, so the Transportation Coordinator has been asked to cancel it. Your driver stays assigned until they do.' - Request still Allocated; trip unchanged; a new TripStatusHistory row 'Cancellation requested by the requester: <reason>'. | I11: Keep the trip. | K11: Not Run
A12: 8 | B12: M-08 | C12: Live progress | D12: ALIAKBAR + AABID | E12: High | F12: My Bookings open on the Allocated request; do not touch it. | G12: 1. Aabid taps On my way (50000). 2. Wait up to 30 seconds. 3. Aabid taps Picked up, then Complete (50042). | H12: Timeline and grid update by themselves after each tap, with a time on each stage reached. | I12: - | K12: Not Run
A13: 9 | B13: M-09 | C13: After Complete | D13: ALIAKBAR | E13: Medium | F13: Straight after the previous step. Flow 3 is not running. | G13: 1. Read the badge and the buttons. | H13: The timeline shows Trip completed, but the request badge still reads Allocated and 'Ask to cancel' is still offered. Only the flow sets the request to Completed. Record what you see. | I13: - | K13: Not Run
A14: 10 | B14: M-10 | C14: Privacy | D14: ALIAKBAR | E14: High | F14: Any request not yet accepted. | G14: 1. Read its detail panel. | H14: No driver, vehicle or availability information. | I14: - | K14: Not Run
A15: 11 | B15: M-11 | C15: Cancel - direct | D15: ALIAKBAR | E15: High | F15: A Held request (book for tomorrow). | G15: 1. Select it; click 'Cancel this booking'. 2. Try to confirm with no reason. 3. Type a reason; click 'Cancel the booking'. 4. Check the row. | H15: - Dialog 'Cancel this booking?' with three consequences; confirm is disabled until a reason is typed. - Green notice 'Your booking was cancelled.' Badge Cancelled. Row: ReqStatus Cancelled, CancellationReason = your text. - Selecting it again shows 'Cancelled: <reason>' and no cancel button. | I15: - | K15: Not Run
A16: 12 | B16: M-12 | C16: Cancel - Awaiting Coordinator | D16: ALIAKBAR | E16: Medium | F16: AUH-11223 Under Maintenance; book the standard booking (escalates). | G16: 1. Select it; read the notice and the button. 2. Cancel it with a reason. | H16: Amber notice that the Coordinator is assigning someone. Button 'Cancel this booking'. It cancels directly. | I16: AUH-11223 back to Available. | K16: Not Run
... A20: 16 | B20: M-16 | C20: Web part settings | D20: Page editor | E20: Low | F20: Edit the page. | G20: 1. Set history count to 2; change the refresh seconds; reload. | H20: Only the 2 newest requests are listed. | I20: Restore the settings. | K20: Not Run

Sheet 4 Driver Dashboard
A1: Driver Dashboard
A2: Keep Aabid's and Mahedi's sessions side by side. Aliakbar books; the drivers act.
A4: Step | B4: ID | C4: Feature | D4: Sign in as | E4: Priority | F4: Set up first (data and state) | G4: Test steps | H4: Expected result | I4: Put back afterwards | J4: Actual result | K4: Status | L4: Notes / Bug ID | M4: Tested by | N4: Date tested
A5: 1 | B5: D-01 | C5: Offer reaches both | D5: ALIAKBAR + drivers | E5: High | F5: Baseline. Both driver pages open and untouched. | G5: 1. Aliakbar books the standard booking. 2. Time how long until each card appears. | H5: Within about 20 seconds, on both screens: a dark banner '1 open ride offer waiting for you. First to accept gets the trip.' and a card. No reload. | I5: Keep the offer open. | K5: Not Run
A6: 2 | B6: D-02 | C6: Offer card | D6: AABID + MAHEDI | E6: High | F6: The open offer. | G6: 1. Read the card on both screens. | H6: - Reference; countdown ticking every second from about 15 minutes. - 'Reem Island Office from Head Office'; When; Type Staff; Vehicle Patrol; Passengers 2; Requested by <Aliakbar's display name>. - Accept and Reject buttons. The requester's phone number is not shown. | I6: - | K6: Not Run
A7: 3 | B7: D-03 | C7: Tab title | D7: AABID | E7: High | F7: The open offer. | G7: 1. Switch to another browser tab; read the Driver tab's title. | H7: '(1) New ride offer'. It returns to the normal title when there are no offers. | I7: - | K7: Not Run
A8: 4 | B8: D-04 | C8: Sound | D8: AABID | E8: Medium | F8: Speakers on. | G8: 1. Click 'Sound: off'. 2. Reload. 3. Aliakbar books a second standard booking; wait 20 seconds. | H8: A two-tone chime plays when switched on; the button reads 'Sound: on' and stays on after reload. It chimes again when the count rises to 2, and the title reads '(2) New ride offers'. | I8: Cancel the second request from Dispatch. | K8: Not Run
A9: 5 | B9: D-05 | C9: Refresh now | D9: MAHEDI | E9: Low | F9: - | G9: 1. Aliakbar books; Mahedi clicks 'Refresh now' at once. | H9: The card appears immediately. | I9: Cancel the request. | K9: Not Run
A10: 6 | B10: D-06 | C10: Accept | D10: AABID | E10: High | F10: Baseline. An open offer from a standard booking is on the driver's screen. | G10: 1. Aabid clicks Accept. 2. Watch Mahedi's screen for 20 seconds. 3. Check TransportRequests, TripAssignments, RideOffers, DriversMaster, VehicleMaster, TripStatusHistory. | H10: - Aabid: button 'Accepting…'; the card moves to My trips today with badge Assigned and the note to tap On my way. - Mahedi: his card and banner disappear by the next refresh. - Request: Allocated, AcceptedTrip set. - Trip: TR-00nn, Assigned, Automatic, IsOverride No, Driver Queinfotech aabid, Vehicle AUH-11223. - Aabid's offer: Accepted, RespondedOn set, Vehicle AUH-11223. Mahedi's offer: Closed (not Expired). - Aabid Status On Trip. AUH-11223 VehStatus On Trip. - History: ToStatus Assigned, 'Accepted from broadcast. Ref <id>'. | I10: Keep the trip for the tap steps. | K10: Not Run
A11: 7 | B11: D-07 | C11: On my way - no reading | D11: AABID | E11: High | F11: Aabid's trip is Assigned. | G11: 1. Leave the opening odometer empty; click 'On my way'. | H11: Red banner 'Enter the opening odometer reading before tapping On my way.' Trip stays Assigned. | I11: - | K11: Not Run
A12: 8 | B12: D-08 | C12: Illegal transition | D12: AABID | E12: High | F12: The same Assigned trip open in two tabs of Aabid's browser. | G12: 1. Tab 1: enter 50000; tap 'On my way'. 2. Tab 2 (not refreshed): enter 50000; tap 'On my way'. | H12: - Tab 1: badge En Route; button 'Picked up'; no odometer field. Trip: En Route, ActualStartTime = now, OpeningReading 50000. History Assigned to En Route. - Tab 2: 'A trip that is En Route cannot be set to En Route.' Nothing is written twice. | I12: - | K12: Not Run
A13: 9 | B13: D-09 | C13: Picked up | D13: AABID | E13: High | F13: Trip En Route. | G13: 1. Click 'Picked up'. | H13: Badge In Transit; ActualPickupTime = now; a closing odometer field and 'Complete' appear. | I13: - | K13: Not Run
A14: 10 | B14: D-10 | C14: Complete - no reading | D14: AABID | E14: High | F14: Trip In Transit. | G14: 1. Click Complete with the reading empty. | H14: Red banner 'Enter the closing odometer reading before tapping Complete.' | I14: - | K14: Not Run
A15: 11 | B15: D-11 | C15: Complete | D15: AABID | E15: High | F15: Trip In Transit, opening reading 50000. | G15: 1. Enter 50042; click Complete. 2. Check the trip, request, Aabid and AUH-11223. | H15: - Card moves to Completed today with the finish time and 'Distance 42 km'. - Trip: Completed, ActualDropTime = now, ClosingReading 50042. History In Transit to Completed. - The web part stops there by design. With no Flow 3, the request still reads Allocated and Aabid and AUH-11223 still read On Trip. | I15: - | K15: Not Run
A16: 12 | B16: D-12 | C16: Next booking after Complete | D16: ALIAKBAR | E16: High | F16: Straight after D-11; Aabid and AUH-11223 still read On Trip. | G16: 1. Book the standard booking; read RideOffers. | H16: Offers for both drivers again. Eligibility is worked out from open trips, not from the Status columns, so the left-over 'On Trip' does not block work. | I16: Set Aabid Status and AUH-11223 VehStatus back to Available by hand. Cancel the request. | K16: Not Run
... A38: 34 | B38: D-34 | C38: Phone | D38: MAHEDI | E38: High | F38: A real phone signed in as Mahedi. | G38: 1. Run a whole trip on the phone: accept, On my way, Picked up, Complete. | H38: No sideways scrolling; buttons and the odometer field are easy to use. | I38: - | K38: Not Run

Sheet 5 Dispatch Dashboard
A1: Dispatch Dashboard
A2: The Coordinator's page. Sign in as Aliakbar.
A4: Step | B4: ID | C4: Feature | D4: Sign in as | E4: Priority | F4: Set up first (data and state) | G4: Test steps | H4: Expected result | I4: Put back afterwards | J4: Actual result | K4: Status | L4: Notes / Bug ID | M4: Tested by | N4: Date tested
A5: 1 | B5: C-01 | C5: Load | D5: ALIAKBAR | E5: High | F5: Baseline, nothing pending. | G5: 1. Open Dispatch. | H5: Caption 'Last refreshed hh:mm. Counters filter the grids below.' Six counters, Ongoing trips, Pending requests, Availability tabs. | I5: - | K5: Not Run
A6: 2 | B6: C-02 | C6: Counters at rest | D6: ALIAKBAR | E6: High | F6: Baseline, nothing pending, no open trips. | G6: 1. Read the counters. | H6: - Ongoing trips 0. Pending requests 0. Allocated pairs 0. - Available drivers 2. - Available vehicles = every vehicle not under maintenance or retired (2 if only AUH-11223 and AUH-01234 remain; record the number). - Completed trips = trips completed this month; record it. | I6: - | K6: Not Run
A7: 3 | B7: C-03 | C7: Availability - drivers | D7: ALIAKBAR | E7: High | F7: Baseline. | G7: 1. Open the Drivers tab. | H7: 'Drivers (2)': Queinfotech aabid, Available, None, cap 1, Yas Island Resort; Queinfotech mahedi, Available, None, cap 2, Al Maryah Tower. Drivers set to IsActive = No are not listed. | I7: - | K7: Not Run
A8: 4 | B8: C-04 | C8: Availability - vehicles | D8: ALIAKBAR | E8: High | F8: Baseline. | G8: 1. Open the Vehicles tab. | H8: AUH-01234 Blue Ford Transit, Cargo Van, Available; AUH-11223 White Nissan Patrol, Patrol, Available; current task None. | I8: - | K8: Not Run
A9: 5 | B9: C-05 | C9: Pending grid | D9: ALIAKBAR | E9: High | F9: Book the standard booking. | G9: 1. Read the Pending requests grid and the counters. | H9: Row: reference · date and time · Staff · Patrol · badge Broadcasting · Assign, Reject, Cancel. Pending requests 1. | I9: Keep the request. | K9: Not Run
A10: 6 | B10: C-06 | C10: Counters as filters | D10: ALIAKBAR | E10: High | F10: One pending request. | G10: 1. Click 'Ongoing trips'; click again. 2. Click 'Pending requests'; click again. 3. Click 'Available drivers'; then 'Available vehicles'. | H10: Ongoing hides the Pending grid; Pending hides the Ongoing grid; a second click restores. The driver and vehicle counters switch the Availability tab. | I10: - | K10: Not Run
A11: 7 | B11: C-07 | C11: Counters that do not filter | D11: ALIAKBAR | E11: Low | F11: - | G11: 1. Click 'Completed trips'; then 'Allocated pairs'. | H11: The design says every counter filters the grids. Record what changes. | I11: - | K11: Not Run
A12: 8 | B12: C-08 | C12: Completed period | D12: ALIAKBAR | E12: Medium | F12: - | G12: 1. Choose 'Last 2 months'. 2. Read the dropdown label. 3. Try to go back to 'This month'. | H12: It should show the chosen option and allow going back. Record what it shows. | I12: - | K12: Not Run
A13: 9 | B13: C-09 | C13: Column filters | D13: ALIAKBAR | E13: Medium | F13: Two or three pending requests of different types. | G13: 1. Click the Request type header; tick Staff; press Escape. 2. Clear. | H13: The popup lists only the values present. Header '▼ filtered (1)'. Escape or a click outside closes it. | I13: - | K13: Not Run
A14: 10 | B14: C-10 | C14: Assign panel | D14: ALIAKBAR | E14: High | F14: The Broadcasting standard booking. | G14: 1. Click Assign. | H14: - 'Assign FB-00nn': Head Office → Reem Island Office · date time · Patrol. - Drivers: Queinfotech aabid '· eligible', Queinfotech mahedi '· eligible', each with an Available badge. - Vehicles: AUH-11223 '· Patrol' with no warning; AUH-01234 '· Cargo Van · different vehicle type'. | I14: - | K14: Not Run
A15: 11 | B15: C-11 | C15: Assign - in policy | D15: ALIAKBAR + drivers | E15: High | F15: Assign panel open; both drivers have the offer card on screen. | G15: 1. Select Queinfotech mahedi and AUH-11223; click Assign. 2. Check the request, trip, offers, Mahedi, AUH-11223, history. 3. Watch both driver screens for 20 seconds. | H15: - No override box. The panel closes and the row leaves Pending requests. - Request Allocated. Trip TR-00nn: Assigned, AllocationMode Manual, AllocatedBy Aliakbar, IsOverride No. - Both offers: Withdrawn (not Closed, not Expired). - Mahedi On Trip; AUH-11223 On Trip. History 'Assigned manually. Ref <id>'. - Aabid's card disappears. Mahedi's card disappears and the trip appears under My trips today with no Accept step. - Allocated pairs 1; Available drivers 1; Available vehicles drops by 1. | I15: Keep the trip. | K15: Not Run
A16: 12 | B16: C-12 | C16: Assigned is not yet ongoing | D16: ALIAKBAR | E16: Medium | F16: Mahedi's trip is Assigned. | G16: 1. Look for it in Ongoing trips. | H16: Not listed: that grid shows En Route and In Transit only. | I16: - | K16: Not Run
... A39: 35 | B39: C-35 | C39: Failure | D39: ALIAKBAR | E39: Medium | F39: - | G39: 1. Go Offline; Refresh; go online; Refresh. | H39: Red banner that the dashboard could not be loaded, warning not to allocate from stale data, with a Reference id. Recovers. | I39: - | K39: Not Run

Sheet 6 Fleet Reports
A1: Fleet Reports
A2: Run after the other sheets so there is data. Sign in as Aliakbar. Use From 01 Oct 2026, To 31 Oct 2026.
A4: Step | B4: ID | C4: Feature | D4: Sign in as | E4: Priority | F4: Set up first (data and state) | G4: Test steps | H4: Expected result | I4: Put back afterwards | J4: Actual result | K4: Status | L4: Notes / Bug ID | M4: Tested by | N4: Date tested
A5: 1 | B5: R-01 | C5: Load | D5: ALIAKBAR | E5: High | F5: - | G5: 1. Open Fleet Reports. | H5: Filter bar From, To, Property, Request type, Vehicle type, Run report. Eight report buttons, one marked 'Restricted · shows individual acceptance rates'. | I5: - | K5: Not Run
A6: 2 | B6: R-02 | C6: Default range | D6: ALIAKBAR | E6: Medium | F6: - | G6: 1. Read the default From and To. | H6: Should be the 1st and last day of this month. Record the dates shown. | I6: - | K6: Not Run
A7: 3 | B7: R-03 | C7: Dropdowns | D7: ALIAKBAR | E7: Medium | F7: - | G7: 1. Open the three dropdowns. | H7: Property: All properties, Al Maryah Tower, Yas Island Resort, Khalifa Industrial Park. Request type: three. Vehicle type: eight. | I7: - | K7: Not Run
A8: 4 | B8: R-04 | C8: Request fulfilment | D8: ALIAKBAR | E8: High | F8: - | G8: 1. Click 'Request fulfilment'. 2. Group TransportRequests by ReqStatus for October and compare. | H8: Raised = all requests created in the range. Allocated = Allocated + Completed. Escalated = Awaiting Coordinator. Rejected and Cancelled match the list. | I8: - | K8: Not Run
A9: 5 | B9: R-05 | C9: Trip summary | D9: ALIAKBAR | E9: High | F9: - | G9: 1. Click 'Trip summary'. 2. Compare with TripAssignments. | H9: One row per trip: Trip, Request, Required, Driver (Queinfotech aabid or mahedi), Vehicle, Status, Distance. The 50000 to 50042 trips show 42. Header 'N rows · generated <time> · live data'. | I9: - | K9: Not Run
A10: 6 | B10: R-06 | C10: Vehicle utilisation | D10: ALIAKBAR | E10: Medium | F10: - | G10: 1. Click 'Vehicle utilisation'. | H10: A row per vehicle used (AUH-11223, and AUH-01234 if you used it) with trips, hours and distance. | I10: - | K10: Not Run
A11: 7 | B11: R-07 | C11: Driver utilisation | D11: ALIAKBAR | E11: Medium | F11: - | G11: 1. Click 'Driver utilisation'. | H11: A row per driver with trips, hours and trips per day (trips divided by 31). | I11: - | K11: Not Run
A12: 8 | B12: R-08 | C12: Broadcast effectiveness | D12: ALIAKBAR | E12: High | F12: - | G12: 1. Click 'Broadcast effectiveness'. 2. Count trips by AllocationMode. | H12: Auto-allocated = Automatic trips; Manually assigned = Manual trips; Escalated = requests now Awaiting Coordinator; Escalation rate; Median seconds to first accept. | I12: - | K12: Not Run
A13: 9 | B13: R-09 | C13: Driver response behaviour | D13: ALIAKBAR | E13: High | F13: - | G13: 1. Click 'Driver response behaviour'. 2. Group RideOffers by Driver and ResponseStatus. | H13: A row for each of the two drivers: Offers received, Accepted, Rejected, Expired, most common reason. Accepted and Rejected match the list. Closed and Withdrawn offers count only towards Offers received. | I13: - | K13: Not Run
A14: 10 | B14: R-10 | C14: Rejection and cancellation | D14: ALIAKBAR | E14: Medium | F14: - | G14: 1. Click 'Rejection and cancellation analysis'. | H14: A row per rejection reason the drivers used, and 'Cancelled by requester or Coordinator' = number of Cancelled requests; largest first. | I14: - | K14: Not Run
A15: 11 | B15: R-11 | C15: Demand by time and route | D15: ALIAKBAR | E15: Medium | F15: - | G15: 1. Click 'Demand by time and route'. | H15: A row per hour of day with requests and the most common route (mostly 'Head Office to Reem Island Office'). | I15: - | K15: Not Run
A16: 12 | B16: R-12 | C16: Filters | D16: ALIAKBAR | E16: Medium | F16: - | G16: 1. Property = Yas Island Resort; run 'Request fulfilment'. 2. Request type = Items or Documents; run it. 3. Vehicle type = Patrol; run 'Trip summary'. | H16: Each narrows the figures to matching requests only. | I16: - | K16: Not Run
... A22: 18 | B22: R-18 | C22: Restricted report hidden | D22: AABID | E22: High | F22: Aabid is in FM Drivers only. | G22: 1. Aabid opens Fleet Reports; counts the buttons. | H22: 7 reports; 'Driver response behaviour' is missing. Record also that the page itself opens for a driver. | I22: - | K22: Not Run

Sheet 7 Full journeys
A1: Full journeys
A2: Whole stories across the web parts with all three people, then permissions and look and feel.
A4: Step | B4: ID | C4: Feature | D4: Sign in as | E4: Priority | F4: Set up first (data and state) | G4: Test steps | H4: Expected result | I4: Put back afterwards | J4: Actual result | K4: Status | L4: Notes / Bug ID | M4: Tested by | N4: Date tested
A5: 1 | B5: X-01 | C5: Automatic, start to finish | D5: All three | E5: High | F5: Baseline. | G5: 1. Aliakbar books the standard booking and stays on the received screen. 2. Both drivers see the card. Aabid accepts. 3. Aliakbar's screen moves to Booking confirmed; he opens Track my ride. 4. Aabid: On my way (50000), Picked up, Complete (50042). 5. Aliakbar checks Dispatch and the Trip summary report. | H5: - Mahedi's card disappears when Aabid accepts. Offers: Aabid Accepted, Mahedi Closed. - Aliakbar sees the driver and car, then each stage as it happens. - Trip Completed, 42 km, four TripStatusHistory rows. Dispatch: it passes through Ongoing trips and ends in Completed trips. - With no flows: the request stays Allocated, Aabid and AUH-11223 stay On Trip, and no emails are sent. | I5: Aabid and AUH-11223 back to Available. | K5: Not Run
A6: 2 | B6: X-02 | C6: One declines, the other drives | D6: All three | E6: High | F6: Baseline. | G6: 1. Aliakbar books. 2. Aabid rejects with 'Already on a trip'. 3. Mahedi accepts and completes. | H6: Aabid's offer Rejected with the reason; Mahedi's Accepted. The trip runs normally. 'Driver response behaviour' later shows one rejection for Aabid. | I6: Mahedi and AUH-11223 back to Available. | K6: Not Run
A7: 3 | B7: X-03 | C7: Driver pulls out, Coordinator re-plans | D7: All three | E7: High | F7: Baseline. | G7: 1. Aliakbar books; Mahedi accepts. 2. Mahedi cancels the trip with a reason. 3. Aliakbar looks at My Bookings and at Dispatch. 4. Aliakbar assigns Aabid with AUH-11223. 5. Aabid completes. | H7: After the cancel: request Awaiting Coordinator, pinned on Dispatch; My Bookings says the Coordinator is assigning someone (not 'Cancelled'). After the reassignment Aabid sees it with no Accept step and the requester sees Aabid's details. | I7: Aabid and AUH-11223 back to Available. | K7: Not Run
A8: 4 | B8: X-04 | C8: Escalation, then manual | D8: ALIAKBAR + AABID | E8: High | F8: AUH-11223 Under Maintenance. | G8: 1. Aliakbar books the standard booking (it escalates). 2. Set AUH-11223 back to Available. 3. Aliakbar refreshes Dispatch, opens Assign, picks Aabid and AUH-11223. 4. Aabid completes. | H8: Path: Awaiting Coordinator → Allocated. Trip AllocationMode Manual. 'Broadcast effectiveness' counts it under Manually assigned. | I8: Aabid and AUH-11223 back to Available. | K8: Not Run
A9: 5 | B9: X-05 | C9: Advance booking | D9: All three | E9: Medium | F9: Baseline. | G9: 1. Aliakbar books for tomorrow (Held). 2. Set ReqStatus = Submitted by hand. 3. Aliakbar opens Dispatch. 4. A driver accepts and completes. | H9: Held → Submitted → Broadcasting (picked up by Dispatch) → Allocated. Neither driver sees it while it is Held. | I9: - | K9: Not Run
A10: 6 | B10: X-06 | C10: Requester changes their mind early | D10: ALIAKBAR | E10: Medium | F10: Baseline. | G10: 1. Book for tomorrow. 2. Cancel it in My Bookings. | H10: Cancelled with the reason; never offered to anyone. | I10: - | K10: Not Run
A11: 7 | B11: X-07 | C11: Requester changes their mind late | D11: All three | E11: High | F11: Baseline. | G11: 1. Aliakbar books; Aabid accepts. 2. Aliakbar uses 'Ask to cancel' in My Bookings. 3. Aliakbar, as Coordinator, tries to act on it from Dispatch. 4. Aabid looks at his Driver Dashboard. | H11: Record how the Coordinator and the driver learn about the request to cancel, and whether the Coordinator can complete the cancellation (C-17). | I11: Aabid cancels the trip; cancel the request from Dispatch. | K11: Not Run
A12: 8 | B12: X-08 | C12: Coordinator rejects | D12: ALIAKBAR | E12: Medium | F12: Baseline. | G12: 1. Book; reject it from Dispatch with a reason; open My Bookings. | H12: Rejected; both offers Withdrawn; the reason is shown to the requester. | I12: - | K12: Not Run
A13: 9 | B13: X-09 | C13: Mahedi carries two trips | D13: All three | E13: Medium | F13: AUH-01234: VehicleType = Patrol, PropertyRef = Al Maryah Tower. | G13: 1. Aliakbar books; Mahedi accepts. 2. Aliakbar books again; read RideOffers; Mahedi accepts. 3. Aliakbar books a third time. | H13: Second booking: offers for Aabid and Mahedi (Mahedi holds 1 of 2). After Mahedi accepts both, the third booking escalates: both Patrols are busy. Dispatch shows Allocated pairs 2. | I13: Mahedi completes both. AUH-01234 back to Cargo Van at Khalifa Industrial Park. Cancel the third request. | K13: Not Run
A14: 10 | B14: X-10 | C14: Three bookings in a minute | D14: All three | E14: Medium | F14: Baseline. | G14: 1. Submit three standard bookings within one minute from two sessions. 2. Check the rows and offers. | H14: Three different references, each matching its item ID, each with its own two offers. | I14: Cancel them. | K14: Not Run
A15: 11 | B15: X-11 | C15: Driver cannot write - master lists | D15: AABID | E15: High | F15: Give FM Drivers Read only on DriversMaster and VehicleMaster. | G15: 1. Aliakbar books; Aabid accepts. 2. Check the trip, Aabid's Status and AUH-11223. | H15: Record the message Aabid sees and the state left behind: is there a trip, and do the driver and vehicle read On Trip? | I15: Restore Contribute. Tidy the trip. | K15: Not Run
A16: 12 | B16: X-12 | C16: Driver cannot write - offers | D16: MAHEDI | E16: Medium | F16: Give FM Drivers Read only on RideOffers. | G16: 1. Mahedi rejects an offer. | H16: 'You do not have permission to write to the RideOffers list. Ask a Fleet Admin to grant your group Contribute on RideOffers. Nothing was saved.' | I16: Restore Contribute. | K16: Not Run
... A25: 21 | B25: X-21 | C25: Browsers | D25: AABID + MAHEDI | E25: Medium | F25: Edge and Chrome. | G25: 1. Open the Driver Dashboard in each. | H25: Works in both, including the chime and tab title. | I25: - | K25: Not Run

Sheet Data Notes
A1: # | B1: List | C1: Point | D1: Why it matters | E1: Suggested action | F1: See step | G1: Confirmed? (Yes / No) | H1: Notes
A2: N-01 | B2: DriversMaster | C2: Other driver rows may still be active | D2: Your earlier list had six drivers. If the four you did not mention are still active and linked to properties, they receive offers nobody can answer, and if Aliakbar's login is still on one of them, Aliakbar is treated as a driver. | E2: Set IsActive = No and clear UserAccount on them. | F2: S-03
A3: N-02 | B3: DLClientMaster | C3: Not supplied | D3: This list decides who can be offered a trip. The pack assumes three rows: Aabid to Yas Island Resort and to Al Maryah Tower, Mahedi to Al Maryah Tower. HomeProperty on DriversMaster does not decide who is offered a trip. | E3: Confirm in the setup step. | F3: S-04
A4: N-03 | B4: DriversMaster | C4: Aabid's home property is now Yas Island Resort | D4: HomeProperty affects three things only: the default pickup when Aabid books a ride himself, the property a no-property pickup is filed under for him, and which properties he sees if he opens Dispatch. It does not affect which trips he is offered. | E4: Keep his Al Maryah Tower link in DLClientMaster so both drivers still share offers. | F4: A-29
A5: N-04 | B5: VehicleMaster | C5: One Patrol for two drivers | D5: The only vehicle either driver can drive is AUH-11223 at Al Maryah Tower, and nothing drivable is based at Aabid's home property, Yas Island Resort. One open trip therefore sends the next request to the Coordinator. Several steps borrow AUH-01234 as a second Patrol. | E5: Expected with this test fleet. | F5: -
A6: N-05 | B6: VehicleMaster | C6: AUH-01234 cannot be allocated automatically | D6: It is a Cargo Van at Khalifa Industrial Park with Aabid as default driver, but neither driver is qualified for Cargo Van or linked to that property. | E6: Fine for testing; a real fleet needs a qualified, linked driver. | F6: A-28
A7: N-06 | B7: Locations | C7: Four locations have no Property | D7: Both airports, Cleveland Clinic Abu Dhabi and Downtown Abu Dhabi. A normal requester cannot book a pickup from them. | E7: Give them a Property, or accept that they are destinations only. | F7: B-32
A8: N-07 | B8: TransportRequests | C8: FB-0020 and FB-0021 are stuck in Broadcasting | D8: Their offer windows closed on 8 and 7 Oct. They are cleared in the setup sheet. | E8: Cancel them from Dispatch. | F8: -
A9: N-08 | B9: Flows | C9: No flow is assumed to be running | D9: So requests never move from Broadcasting to Awaiting Coordinator by themselves, a completed trip leaves its request on Allocated and its driver and vehicle on On Trip, and no emails are sent. Steps say where to fix this by hand. | E9: Build the flows, then use module 09 of the live-data workbook. | F9: -
B11: Note | C11: Source: the DriversMaster and VehicleMaster rows you pasted on 9 Oct 2026, plus the Locations, VehicleTypes, AllocationRules and TransportRequests data from earlier the same day.

Sheet Code Review Risks
A1: # | B1: Area | C1: What I expect to go wrong | D1: Why (from reading the code) | E1: Where in the code | F1: Confirm with step | G1: Confirmed? (Yes / No) | H1: Notes
A2: CR-01 | B2: My Bookings | C2: Cancelling while Broadcasting does nothing but says a driver accepted | D2: The screen offers 'Ask to cancel' for Broadcasting. The service only cancels Submitted, Held and Awaiting Coordinator; otherwise it returns the 'driver has already accepted' message. With no trip there is nothing to write. | E2: src/common/rules/statusTransitions.ts (cancellationNeedsCoordinator); src/common/services/DispatchService.ts (cancel) | F2: M-05
A3: CR-02 | B3: Dispatch | C3: No way to cancel an Allocated request | D3: Cancel exists only on Pending rows; the Ongoing grid has no actions. | E3: src/webparts/dispatchDashboard/components/DispatchDashboard.tsx | F3: C-17
A4: CR-03 | B4: Dispatch | C4: Reassign is not reachable | D4: DispatchService.reassign has no caller. | E4: src/common/services/DispatchService.ts (reassign) | F4: C-16
A5: CR-04 | B5: Dispatch | C5: Set ETA is not reachable | D5: DispatchService.setEta has no caller, so ETA always reads 'not set'. | E5: src/common/services/DispatchService.ts (setEta) | F5: C-15
A6: CR-05 | B6: Dispatch | C6: An expired broadcast looks like a live one | D6: Nothing on the page compares OfferClosesAt with the current time, so without Flow 2 the Coordinator is never told. | E6: src/webparts/dispatchDashboard/components/DispatchDashboard.tsx | F6: C-31
A7: CR-06 | B7: Dispatch | C7: Assign panel never shows the on-leave verdict | D7: It passes an empty list of availability blocks to the eligibility check and does not look at Status, so a driver on leave can be assigned with no override reason. | E7: DispatchDashboard.tsx (AssignmentPanel, blocks: []) | F7: C-21
