Workbook

Sheet Read Me
A1: Fleet Booking and Dispatch Portal - Test Cases
A3: What this is | B3: A step-by-step test pack for the five web parts, the allocation engine that runs in the browser, and the eight Power Automate flows from Build Guide v4. Expected results were written from the source code and the seed script, not only from the documents.
A4: Sheets | B4: Summary: live pass and fail counts per module. Test Cases: every test, in the order to run them. Code Review Risks: places where reading the code suggests the behaviour will differ from the design. Each points to the test that confirms it. Test Data: what the seed script loads, so you know what each screen should show. Bug Log: where to record anything that fails.
A5: Cells you fill in | B5: Only the yellow columns on Test Cases: Actual result, Status, Notes / Bug ID, Tested by, Date tested. On Code Review Risks fill Confirmed? and Notes. On Bug Log fill every column.
A6: Status values | B6: Not Run (default), Pass, Fail, Blocked (could not be run, for example no second driver account or a flow not built yet), N/A.
A7: Order to run | B7: 1. Module 01 Setup, exactly in order. SET-012 must be done before you open the Dispatch page for the first time. 2. Modules 02 to 08, which need no flows. 3. Module 09 once each flow is built, in the guide's build order. 4. Modules 10 to 12. Re-seed with -Force (SET-008) whenever the data gets too tangled.
A8: Accounts | B8: TESTER: your own login, in all five FM groups, linked to driver Rashid Al Mansoori. DRIVER-B: optional second login linked to Suresh Nair (pass it as -OtherDriverUpns when seeding and add it to FM Drivers). Needed for the accept race. PLAIN: optional login in none of the FM groups. Needed for role and privacy tests.
A9: 'Needs flows' column | B9: No: testable with the web parts alone. Yes: needs the Power Automate flow named in the test. Every driver and Coordinator action runs in the browser, so most of the pack is testable before any flow exists.
A10: Type column | B10: Positive: the normal path. Negative: something that must be refused. Edge case: an unusual but valid situation. Check: an inspection where you record what you find.
A11: Where to look | B11: Most expected results name list columns. Keep the SharePoint lists open in another tab: TransportRequests, RideOffers, TripAssignments, TripStatusHistory, DriversMaster, VehicleMaster. Keep the browser console open (F12); the engine logs lines starting [FleetPortal].
A12: Polling | B12: Driver page refreshes every 20 s, My Bookings every 30 s, Dispatch every 60 s, the booking wizard every 10 s. Flows wake about every 5 minutes; wait 10 minutes before failing any email test.
A13: Example of a filled row | B13: Actual result: 'Request went to Awaiting Coordinator, no offers created, console showed the escalation report.' Status: Pass Notes: (blank) Tested by: MAS Date tested: 12-Oct-2026

Sheet Summary
A1: Test progress
A2: Counts update as you set the Status column on the Test Cases sheet.
A4: Module | B4: Total | C4: Pass | D4: Fail | E4: Blocked | F4: N/A | G4: Not Run | H4: % run | I4: % passed of run
A5: 01 Setup and environment | B5: =COUNTIF('Test Cases'!$B:$B,$A5) -> 13 | C5: =COUNTIFS('Test Cases'!$B:$B,$A5,'Test Cases'!$L:$L,"Pass") -> 0 | D5: =COUNTIFS('Test Cases'!$B:$B,$A5,'Test Cases'!$L:$L,"Fail") -> 0 | E5: =COUNTIFS('Test Cases'!$B:$B,$A5,'Test Cases'!$L:$L,"Blocked") -> 0 | F5: =COUNTIFS('Test Cases'!$B:$B,$A5,'Test Cases'!$L:$L,"N/A") -> 0 | G5: =COUNTIFS('Test Cases'!$B:$B,$A5,'Test Cases'!$L:$L,"Not Run") -> 13 | H5: =IF(B5=0,0,(B5-G5)/B5) -> 0 | I5: =IF((C5+D5)=0,0,C5/(C5+D5)) -> 0
A6: 02 Roles and access | B6: =COUNTIF('Test Cases'!$B:$B,$A6) -> 10 | C6: =COUNTIFS('Test Cases'!$B:$B,$A6,'Test Cases'!$L:$L,"Pass") -> 0 | D6: =COUNTIFS('Test Cases'!$B:$B,$A6,'Test Cases'!$L:$L,"Fail") -> 0 | E6: =COUNTIFS('Test Cases'!$B:$B,$A6,'Test Cases'!$L:$L,"Blocked") -> 0 | F6: =COUNTIFS('Test Cases'!$B:$B,$A6,'Test Cases'!$L:$L,"N/A") -> 0 | G6: =COUNTIFS('Test Cases'!$B:$B,$A6,'Test Cases'!$L:$L,"Not Run") -> 10 | H6: =IF(B6=0,0,(B6-G6)/B6) -> 0 | I6: =IF((C6+D6)=0,0,C6/(C6+D6)) -> 0
A7: 03 Book a Ride | B7: =COUNTIF('Test Cases'!$B:$B,$A7) -> 42 | C7: =COUNTIFS('Test Cases'!$B:$B,$A7,'Test Cases'!$L:$L,"Pass") -> 0 | D7: =COUNTIFS('Test Cases'!$B:$B,$A7,'Test Cases'!$L:$L,"Fail") -> 0 | E7: =COUNTIFS('Test Cases'!$B:$B,$A7,'Test Cases'!$L:$L,"Blocked") -> 0 | F7: =COUNTIFS('Test Cases'!$B:$B,$A7,'Test Cases'!$L:$L,"N/A") -> 0 | G7: =COUNTIFS('Test Cases'!$B:$B,$A7,'Test Cases'!$L:$L,"Not Run") -> 42 | H7: =IF(B7=0,0,(B7-G7)/B7) -> 0 | I7: =IF((C7+D7)=0,0,C7/(C7+D7)) -> 0
A8: 04 Allocation engine (broadcast) | B8: =COUNTIF('Test Cases'!$B:$B,$A8) -> 20 | C8: =COUNTIFS('Test Cases'!$B:$B,$A8,'Test Cases'!$L:$L,"Pass") -> 0 | D8: =COUNTIFS('Test Cases'!$B:$B,$A8,'Test Cases'!$L:$L,"Fail") -> 0 | E8: =COUNTIFS('Test Cases'!$B:$B,$A8,'Test Cases'!$L:$L,"Blocked") -> 0 | F8: =COUNTIFS('Test Cases'!$B:$B,$A8,'Test Cases'!$L:$L,"N/A") -> 0 | G8: =COUNTIFS('Test Cases'!$B:$B,$A8,'Test Cases'!$L:$L,"Not Run") -> 20 | H8: =IF(B8=0,0,(B8-G8)/B8) -> 0 | I8: =IF((C8+D8)=0,0,C8/(C8+D8)) -> 0
A9: 05 My Bookings | B9: =COUNTIF('Test Cases'!$B:$B,$A9) -> 23 | C9: =COUNTIFS('Test Cases'!$B:$B,$A9,'Test Cases'!$L:$L,"Pass") -> 0 | D9: =COUNTIFS('Test Cases'!$B:$B,$A9,'Test Cases'!$L:$L,"Fail") -> 0 | E9: =COUNTIFS('Test Cases'!$B:$B,$A9,'Test Cases'!$L:$L,"Blocked") -> 0 | F9: =COUNTIFS('Test Cases'!$B:$B,$A9,'Test Cases'!$L:$L,"N/A") -> 0 | G9: =COUNTIFS('Test Cases'!$B:$B,$A9,'Test Cases'!$L:$L,"Not Run") -> 23 | H9: =IF(B9=0,0,(B9-G9)/B9) -> 0 | I9: =IF((C9+D9)=0,0,C9/(C9+D9)) -> 0
A10: 06 Driver Dashboard | B10: =COUNTIF('Test Cases'!$B:$B,$A10) -> 36 | C10: =COUNTIFS('Test Cases'!$B:$B,$A10,'Test Cases'!$L:$L,"Pass") -> 0 | D10: =COUNTIFS('Test Cases'!$B:$B,$A10,'Test Cases'!$L:$L,"Fail") -> 0 | E10: =COUNTIFS('Test Cases'!$B:$B,$A10,'Test Cases'!$L:$L,"Blocked") -> 0 | F10: =COUNTIFS('Test Cases'!$B:$B,$A10,'Test Cases'!$L:$L,"N/A") -> 0 | G10: =COUNTIFS('Test Cases'!$B:$B,$A10,'Test Cases'!$L:$L,"Not Run") -> 36 | H10: =IF(B10=0,0,(B10-G10)/B10) -> 0 | I10: =IF((C10+D10)=0,0,C10/(C10+D10)) -> 0
A11: 07 Dispatch Dashboard | B11: =COUNTIF('Test Cases'!$B:$B,$A11) -> 37 | C11: =COUNTIFS('Test Cases'!$B:$B,$A11,'Test Cases'!$L:$L,"Pass") -> 0 | D11: =COUNTIFS('Test Cases'!$B:$B,$A11,'Test Cases'!$L:$L,"Fail") -> 0 | E11: =COUNTIFS('Test Cases'!$B:$B,$A11,'Test Cases'!$L:$L,"Blocked") -> 0 | F11: =COUNTIFS('Test Cases'!$B:$B,$A11,'Test Cases'!$L:$L,"N/A") -> 0 | G11: =COUNTIFS('Test Cases'!$B:$B,$A11,'Test Cases'!$L:$L,"Not Run") -> 37 | H11: =IF(B11=0,0,(B11-G11)/B11) -> 0 | I11: =IF((C11+D11)=0,0,C11/(C11+D11)) -> 0
A12: 08 Fleet Reports | B12: =COUNTIF('Test Cases'!$B:$B,$A12) -> 23 | C12: =COUNTIFS('Test Cases'!$B:$B,$A12,'Test Cases'!$L:$L,"Pass") -> 0 | D12: =COUNTIFS('Test Cases'!$B:$B,$A12,'Test Cases'!$L:$L,"Fail") -> 0 | E12: =COUNTIFS('Test Cases'!$B:$B,$A12,'Test Cases'!$L:$L,"Blocked") -> 0 | F12: =COUNTIFS('Test Cases'!$B:$B,$A12,'Test Cases'!$L:$L,"N/A") -> 0 | G12: =COUNTIFS('Test Cases'!$B:$B,$A12,'Test Cases'!$L:$L,"Not Run") -> 23 | H12: =IF(B12=0,0,(B12-G12)/B12) -> 0 | I12: =IF((C12+D12)=0,0,C12/(C12+D12)) -> 0
A13: 09 Power Automate flows | B13: =COUNTIF('Test Cases'!$B:$B,$A13) -> 38 | C13: =COUNTIFS('Test Cases'!$B:$B,$A13,'Test Cases'!$L:$L,"Pass") -> 0 | D13: =COUNTIFS('Test Cases'!$B:$B,$A13,'Test Cases'!$L:$L,"Fail") -> 0 | E13: =COUNTIFS('Test Cases'!$B:$B,$A13,'Test Cases'!$L:$L,"Blocked") -> 0 | F13: =COUNTIFS('Test Cases'!$B:$B,$A13,'Test Cases'!$L:$L,"N/A") -> 0 | G13: =COUNTIFS('Test Cases'!$B:$B,$A13,'Test Cases'!$L:$L,"Not Run") -> 38 | H13: =IF(B13=0,0,(B13-G13)/B13) -> 0 | I13: =IF((C13+D13)=0,0,C13/(C13+D13)) -> 0
A14: 10 Permissions and security | B14: =COUNTIF('Test Cases'!$B:$B,$A14) -> 9 | C14: =COUNTIFS('Test Cases'!$B:$B,$A14,'Test Cases'!$L:$L,"Pass") -> 0 | D14: =COUNTIFS('Test Cases'!$B:$B,$A14,'Test Cases'!$L:$L,"Fail") -> 0 | E14: =COUNTIFS('Test Cases'!$B:$B,$A14,'Test Cases'!$L:$L,"Blocked") -> 0 | F14: =COUNTIFS('Test Cases'!$B:$B,$A14,'Test Cases'!$L:$L,"N/A") -> 0 | G14: =COUNTIFS('Test Cases'!$B:$B,$A14,'Test Cases'!$L:$L,"Not Run") -> 9 | H14: =IF(B14=0,0,(B14-G14)/B14) -> 0 | I14: =IF((C14+D14)=0,0,C14/(C14+D14)) -> 0
A15: 11 End-to-end scenarios | B15: =COUNTIF('Test Cases'!$B:$B,$A15) -> 10 | C15: =COUNTIFS('Test Cases'!$B:$B,$A15,'Test Cases'!$L:$L,"Pass") -> 0 | D15: =COUNTIFS('Test Cases'!$B:$B,$A15,'Test Cases'!$L:$L,"Fail") -> 0 | E15: =COUNTIFS('Test Cases'!$B:$B,$A15,'Test Cases'!$L:$L,"Blocked") -> 0 | F15: =COUNTIFS('Test Cases'!$B:$B,$A15,'Test Cases'!$L:$L,"N/A") -> 0 | G15: =COUNTIFS('Test Cases'!$B:$B,$A15,'Test Cases'!$L:$L,"Not Run") -> 10 | H15: =IF(B15=0,0,(B15-G15)/B15) -> 0 | I15: =IF((C15+D15)=0,0,C15/(C15+D15)) -> 0
A16: 12 Interface, accessibility and resilience | B16: =COUNTIF('Test Cases'!$B:$B,$A16) -> 16 | C16: =COUNTIFS('Test Cases'!$B:$B,$A16,'Test Cases'!$L:$L,"Pass") -> 0 | D16: =COUNTIFS('Test Cases'!$B:$B,$A16,'Test Cases'!$L:$L,"Fail") -> 0 | E16: =COUNTIFS('Test Cases'!$B:$B,$A16,'Test Cases'!$L:$L,"Blocked") -> 0 | F16: =COUNTIFS('Test Cases'!$B:$B,$A16,'Test Cases'!$L:$L,"N/A") -> 0 | G16: =COUNTIFS('Test Cases'!$B:$B,$A16,'Test Cases'!$L:$L,"Not Run") -> 16 | H16: =IF(B16=0,0,(B16-G16)/B16) -> 0 | I16: =IF((C16+D16)=0,0,C16/(C16+D16)) -> 0
A17: All modules | B17: =SUM(B5:B16) -> 277 | C17: =SUM(C5:C16) -> 0 | D17: =SUM(D5:D16) -> 0 | E17: =SUM(E5:E16) -> 0 | F17: =SUM(F5:F16) -> 0 | G17: =SUM(G5:G16) -> 277 | H17: =IF(B17=0,0,(B17-G17)/B17) -> 0 | I17: =IF((C17+D17)=0,0,C17/(C17+D17)) -> 0
A19: High priority, not yet passed | B19: =COUNTIFS('Test Cases'!$F:$F,"High",'Test Cases'!$L:$L,"<>Pass")-COUNTIFS('Test Cases'!$F:$F,"High",'Test Cases'!$L:$L,"N/A") -> 116
A20: Tests that need flows | B20: =COUNTIF('Test Cases'!$G:$G,"Yes") -> 46
A21: Tests runnable without flows | B21: =COUNTIF('Test Cases'!$G:$G,"No") -> 231

Sheet Test Cases
A1: ID | B1: Module | C1: Feature | D1: Sign in as | E1: Type | F1: Priority | G1: Needs flows | H1: Preconditions | I1: Test steps | J1: Expected result | K1: Actual result | L1: Status | M1: Notes / Bug ID | N1: Tested by | O1: Date tested
A2: SET-001 | B2: 01 Setup and environment | C2: Tooling | D2: - | E2: Check | F2: High | G2: No | H2: Node 22.14 or later (below 23) installed. | I2: 1. Open a terminal in the project folder. 2. Run: npm install | J2: Install finishes without errors and a node_modules folder exists. | L2: Not Run
A3: SET-002 | B3: 01 Setup and environment | C3: Tooling | D3: - | E3: Check | F3: High | G3: No | H3: SET-001 passed. | I3: 1. Run: npx heft build | J3: Build finishes with no TypeScript or lint errors. | L3: Not Run
A4: SET-003 | B4: 01 Setup and environment | C4: Tooling | D4: - | E4: Check | F4: Medium | G4: No | H4: SET-001 passed. | I4: 1. Run: npx heft test | J4: The unit tests in src/common/rules/dispatchRules.test.ts run and all pass. Record the pass and fail counts in Actual result. | L4: Not Run
A5: SET-004 | B5: 01 Setup and environment | C5: Lists | D5: Site owner | E5: Check | F5: High | G5: No | H5: PnP.PowerShell installed. You are an owner of the test site. | I5: 1. Run scripts/1-Provision-Lists.ps1 with -SiteUrl and -TesterUpn (your own login). 2. Open Site contents. | J5: - These lists exist: PropertyMaster, DLClientMaster, VehicleTypes, Locations, DriversMaster, VehicleMaster, AllocationRules, TransportRequests, TripAssignments, RideOffers, TripStatusHistory, AvailabilityBlocks, NotificationLog, Templates, ReportSnapshot. - Five groups exist: FM Requesters, FM Drivers, FM Coordinators, FM Admins, FM Viewers. - Your account is a member of all five. | L5: Not Run
A6: SET-005 | B6: 01 Setup and environment | C6: Lists | D6: Site owner | E6: Check | F6: Medium | G6: No | H6: SET-004 passed. | I6: 1. Run scripts/1-Provision-Lists.ps1 a second time with the same parameters. | J6: The script reports that everything already exists and creates no duplicate lists, columns or groups. | L6: Not Run
A7: SET-006 | B7: 01 Setup and environment | C7: Seed data | D7: Site owner | E7: Check | F7: High | G7: No | H7: SET-004 passed. Transactional lists are empty. | I7: 1. Run scripts/2-Seed-TestData.ps1 with -SiteUrl and -TesterUpn. Add -OtherDriverUpns with one or two colleague logins if you have them. 2. Open each list and count the rows. | J7: - PropertyMaster 2, VehicleTypes 8, Locations 10, DriversMaster 6, DLClientMaster 7, VehicleMaster 8, AllocationRules 6, AvailabilityBlocks 2. - TransportRequests 6 (FB-0001 to FB-0006, one per status), RideOffers 7, TripAssignments 2, TripStatusHistory 6, NotificationLog 3. - DriversMaster row 'Rashid Al Mansoori' has your account in UserAccount. | L7: Not Run
A8: SET-007 | B8: 01 Setup and environment | C8: Seed data | D8: Site owner | E8: Negative | F8: Low | G8: No | H8: SET-006 passed. | I8: 1. Run scripts/2-Seed-TestData.ps1 again without -Force. | J8: The script warns that TransportRequests already holds data and stops. No duplicate rows are created. | L8: Not Run
A9: SET-008 | B9: 01 Setup and environment | C9: Seed data | D9: Site owner | E9: Check | F9: Low | G9: No | H9: You are happy to lose the current test transactions. | I9: 1. Run scripts/2-Seed-TestData.ps1 with -Force. | J9: TripStatusHistory, RideOffers, TripAssignments, TransportRequests and NotificationLog are cleared and reseeded. Master lists are not duplicated. Use this to reset between test rounds. | L9: Not Run
A10: SET-009 | B10: 01 Setup and environment | C10: Local run | D10: TESTER | E10: Check | F10: High | G10: No | H10: SET-002 passed. You can sign in to the SharePoint site named in config/serve.json. | I10: 1. Run: npx heft trust-dev-cert (first time only). 2. Run: npm start 3. In the workbench that opens, add each of the five web parts in turn. | J10: - The workbench opens on the configured site. - The toolbox lists five web parts: Book a Ride, My Bookings, Driver Dashboard, Dispatch Dashboard, Fleet Reports. - Each one renders without a red error banner. | L10: Not Run
A11: SET-010 | B11: 01 Setup and environment | C11: Package | D11: - | E11: Check | F11: High | G11: No | H11: SET-002 passed. | I11: 1. Run: npx heft clean 2. Run: npx heft build --production 3. Run: npx heft package-solution --production 4. Check the size of sharepoint/solution/fleet-booking-dispatch.sppkg. | J11: - The .sppkg file is created. - It is roughly 400 KB and contains exactly five .js bundles (one per web part). | L11: Not Run
A12: SET-011 | B12: 01 Setup and environment | C12: Deploy | D12: Tenant admin | E12: Check | F12: High | G12: No | H12: SET-010 passed. | I12: 1. Upload the .sppkg to the tenant App Catalog and tick 'Make this solution available to all sites'. 2. Create five pages on the site: Book.aspx, MyBookings.aspx, Driver.aspx, Dispatch.aspx, Reports.aspx. 3. Put one web part on each page and publish. | J12: All five pages load for your account with no error banner. Use these pages for every test below. | L12: Not Run
A13: SET-012 | B13: 01 Setup and environment | C13: Seed baseline | D13: TESTER | E13: Check | F13: High | G13: No | H13: Fresh seed (SET-006 or SET-008). You have NOT opened Dispatch.aspx yet. | I13: 1. Open Driver.aspx FIRST and note what you see. 2. Open MyBookings.aspx. 3. Only then open Dispatch.aspx. | J13: - Driver: banner shows 1 open offer (FB-0002) with a countdown of about 30 minutes; one trip card FB-0004 with status En Route. - My Bookings: 6 rows, FB-0001 to FB-0006, one per status. - Dispatch: Ongoing 1, Pending 3, Completed 1, Allocated pairs 1. FB-0003 pinned to the top. - Important: opening Dispatch runs the sweep, which broadcasts FB-0001. After that, FB-0001 reads Broadcasting and Driver.aspx shows 2 open offers. This is designed behaviour (see ALC-012). | L13: Not Run
... A278: NFR-016 | B278: 12 Interface, accessibility and resilience | C278: Simulator script | D278: Site owner | E278: Check | F278: Low | G278: No | H278: scripts/3-Simulate-Flows.ps1. | I278: 1. Run it with -Action Status. 2. Run -Action Claim against a Broadcasting request. | J278: The script reports each request's status and can perform the claim. Record any errors; the script reads a column called 'Status' while the lists use 'ReqStatus', so it may be out of date. | L278: Not Run

Sheet Code Review Risks
A1: # | B1: Area | C1: What I expect to go wrong | D1: Why (from reading the code) | E1: Where in the code | F1: Confirm with test | G1: Confirmed? (Yes / No) | H1: Notes
A2: R-01 | B2: Driver Dashboard | C2: Accepting when no vehicle is free shows the 'taken' wording | D2: acceptOffer returns NO_VEHICLE 'No vehicle is available for this trip'. The dashboard shows every such result in the same box, which always adds 'Another driver accepted that trip first.' With fresh seed data this happens on FB-0002. | E2: src/webparts/driverDashboard/components/DriverDashboard.tsx (takenNotice) | F2: DRV-014
A3: R-02 | B3: My Bookings | C3: Cancelling while Broadcasting does nothing but says a driver accepted | D3: The screen offers 'Ask to cancel' for Broadcasting. The service only cancels Submitted, Held and Awaiting Coordinator; for anything else it returns the 'A driver has already accepted this trip' message. With no trip there is nothing to write, so the request keeps broadcasting. | E3: src/common/rules/statusTransitions.ts (cancellationNeedsCoordinator); src/common/services/DispatchService.ts (cancel) | F3: MYB-017
A4: R-03 | B4: Dispatch Dashboard | C4: No way to cancel an Allocated request | D4: Cancel is only on rows of the Pending grid. Allocated requests are not in that grid and the Ongoing grid has no actions, so the Coordinator cannot act on a requester's 'Ask to cancel'. | E4: src/webparts/dispatchDashboard/components/DispatchDashboard.tsx (ongoingColumns, pendingColumns) | F4: DSP-030
A5: R-04 | B5: Dispatch Dashboard | C5: Reassign is not reachable from the interface | D5: DispatchService.reassign exists but no component calls it. | E5: src/common/services/DispatchService.ts (reassign) | F5: DSP-031
A6: R-05 | B6: Dispatch Dashboard | C6: Set ETA is not reachable from the interface | D6: DispatchService.setEta exists but no component calls it. The ETA shown on FB-0004 comes from the seed. | E6: src/common/services/DispatchService.ts (setEta) | F6: DSP-032
A7: R-06 | B7: Dispatch Dashboard | C7: Assign panel never shows the on-leave verdict | D7: The panel passes an empty list of availability blocks to the eligibility check, so 'On leave during the trip window' cannot appear. Ali Hassan is likely to read 'eligible' beside an On Leave badge, and assigning him needs no override reason. | E7: src/webparts/dispatchDashboard/components/DispatchDashboard.tsx (AssignmentPanel, blocks: []) | F7: DSP-018
A8: R-07 | B8: Dispatch Dashboard | C8: Assign panel ignores trips that are only Assigned | D8: The panel builds its open-trip list from Ongoing trips (En Route and In Transit). A driver or vehicle on an Assigned trip is not flagged as at cap or busy. | E8: src/webparts/dispatchDashboard/components/DispatchDashboard.tsx (openTrips from snapshot.ongoingTrips) | F8: DSP-023
A9: R-08 | B9: Dispatch Dashboard | C9: Held requests are invisible to the Coordinator | D9: The snapshot reads Submitted, Broadcasting, Awaiting Coordinator, Allocated and Completed only. | E9: src/common/services/DispatchService.ts (getSnapshot) | F9: DSP-007
A10: R-09 | B10: Dispatch Dashboard | C10: Completed trips and Allocated pairs counters do not filter | D10: Only the Ongoing and Pending counters change which grid is shown; the driver and vehicle counters switch a tab. The other two only highlight. | E10: src/webparts/dispatchDashboard/components/DispatchDashboard.tsx (visibleTrips, visibleRequests) | F10: DSP-010
A11: R-10 | B11: Dispatch Dashboard | C11: Completed period dropdown always reads 'This month' | D11: The dropdown's value is bound to the period start, which is also the value of the first option. After choosing 'Last 2 months' the label snaps back to 'This month', and there is no working way to return to the current month. | E11: src/webparts/dispatchDashboard/components/DispatchDashboard.tsx (period Select) | F11: DSP-011
A12: R-11 | B12: Dispatch Dashboard | C12: Seeded counter figures differ from TESTING.md | D12: Worked from the code and seed: 5 available drivers and 6 available vehicles for a tester scoped to both properties. TESTING.md says 3 and 5. | E12: src/common/services/DispatchService.ts (getSnapshot); TESTING.md | F12: DSP-002
A13: R-12 | B13: Book a Ride | C13: Default pickup may not be Dubai Head Office | D13: The default is the first location of the home property, and locations are read in Title order, so 'Al Barsha Clinic' sorts first for Dubai. | E13: src/webparts/bookARide/components/BookARide.tsx (home default); src/common/services/MasterDataService.ts (orderBy Title) | F13: BAR-002
... A27: R-26 | B27: Documentation | C27: README.md and TESTING.md describe the old flow-URL design | D27: Both still say writes fail until flow URLs are pasted into the property pane, and mark driver and coordinator actions as untestable without flows. Those actions now run in the browser. ARCHITECTURE.md is the current description. | E27: README.md; TESTING.md | F27: -
B29: Note | C29: These come from reading the source, not from running the app. Nothing here is confirmed until the linked test has been run. Source: project code as at commit 05e84ee and Fleet-Power-Automate-Build-Guide-v4.pdf.

Sheet Test Data
A1: Source: scripts/2-Seed-TestData.ps1. Times are relative to the moment the seed was run.
A3: Drivers (DriversMaster)
A4: Driver | B4: Home property | C4: Also allocated to | D4: Qualified for | E4: Status | F4: Cap | G4: Licence expires | H4: Why it is in the seed
A5: Rashid Al Mansoori | B5: Dubai Head Office | C5: Abu Dhabi Site | D5: Patrol, Pathfinder, Kicks / Creta, Others | E5: On Trip | F5: 2 | G5: +2 years | H5: Your account. Multi-property. Holds FB-0004.
A6: Suresh Nair | B6: Dubai Head Office | C6: - | D6: Patrol, Pathfinder, Kicks / Creta, Others | E6: Available | F6: 1 | G6: +1 year | H6: Second Dubai passenger driver, for the race. Account only if -OtherDriverUpns given.
A7: Mohammed Iqbal | B7: Dubai Head Office | C7: - | D7: All four vans, Others | E7: Available | F7: 1 | G7: +8 months | H7: Van driver. Must not get passenger offers.
A8: Jomon Varghese | B8: Abu Dhabi Site | C8: - | D8: Patrol, Pathfinder, Kicks / Creta, Others | E8: Available | F8: 1 | G8: +3 years | H8: Abu Dhabi only. Must not get Dubai offers.
A9: Ali Hassan | B9: Dubai Head Office | C9: - | D9: Patrol, Pathfinder, Kicks / Creta, Others | E9: On Leave | F9: 1 | G9: +1 year | H9: Leave block from 2 days ago to 5 days ahead.
A10: Arun Prasad | B10: Dubai Head Office | C10: - | D10: All four vans, Others | E10: Available | F10: 1 | G10: +10 days | H10: Licence check. Excluded from trips after expiry.
A12: Vehicles (VehicleMaster)
A13: Plate | B13: Type | C13: Vehicle | D13: Property | E13: Default driver | F13: Status | H13: Note
A14: A 12345 | B14: Patrol | C14: White Nissan Patrol | D14: Dubai Head Office | E14: Rashid Al Mansoori | F14: On Trip | H14: On FB-0004. The only Dubai Patrol.
A15: B 23456 | B15: Pathfinder | C15: Silver Nissan Pathfinder | D15: Dubai Head Office | E15: Suresh Nair | F15: Available
A16: C 34567 | B16: Kicks / Creta | C16: Grey Hyundai Creta | D16: Dubai Head Office | E16: - | F16: Available
A17: D 45678 | B17: Cargo Van | C17: White Toyota Hiace | D17: Dubai Head Office | E17: Mohammed Iqbal | F17: Available
A18: E 56789 | B18: Chiller Van | C18: White Isuzu NPR | D18: Dubai Head Office | E18: - | F18: Under Maintenance | H18: Maintenance block. The only Chiller Van.
A19: F 67890 | B19: Hot and Cold Van | C19: White Isuzu NQR | D19: Dubai Head Office | E19: - | F19: Available
A20: G 78901 | B20: Animal Van | C20: Blue Mitsubishi Canter | D20: Dubai Head Office | E20: - | F20: Available
A21: H 89012 | B21: Patrol | C21: Black Nissan Patrol | D21: Abu Dhabi Site | E21: Jomon Varghese | F21: Available | H21: The only Abu Dhabi vehicle.
A23: Requests (TransportRequests)
A24: Reference | B24: Status | C24: Type | D24: Route | E24: Vehicle type | F24: Required | H24: What it proves
A25: FB-0001 | B25: Submitted | C25: Staff | D25: Dubai Head Office to Al Barsha Clinic | E25: Kicks / Creta | F25: +3 hours | H25: Swept and broadcast the first time Dispatch is opened.
A26: FB-0002 | B26: Broadcasting | C26: Client or Client Guest | D26: Dubai International T3 to Downtown Client Office | E26: Patrol | F26: +2 hours | H26: Open offers to Rashid and Suresh, 30-minute window. Accepting it finds no free Patrol.
A27: FB-0003 | B27: Awaiting Coordinator | C27: Items or Documents | D27: Jebel Ali Warehouse to Mussafah Depot | E27: Cargo Van | F27: +5 hours | H27: Escalated, two rejections with reasons.
A28: FB-0004 | B28: Allocated | C28: Staff | D28: Marina Staff Residence to Dubai Head Office | E28: Patrol | F28: -40 minutes | H28: Trip En Route, ETA 12 min, opening reading 84120.
A29: FB-0005 | B29: Completed | C29: Client or Client Guest | D29: Downtown Client Office to Dubai International T3 | E29: Pathfinder | F29: -6 hours | H29: Completed trip, 42 km (61230 to 61272).
A30: FB-0006 | B30: Cancelled | C30: Staff | D30: Dubai Head Office to Marina Staff Residence | E30: Kicks / Creta | F30: -3 hours | H30: Cancelled with reason 'Meeting moved to Teams.'
A32: Locations
A33: Location | B33: Property | C33: Category
A34: Dubai Head Office | B34: Dubai Head Office | C34: Office
A35: Jebel Ali Warehouse | B35: Dubai Head Office | C35: Warehouse
A36: Dubai International T3 | B36: Dubai Head Office | C36: Airport
A37: Al Barsha Clinic | B37: Dubai Head Office | C37: Hospital
A38: Marina Staff Residence | B38: Dubai Head Office | C38: Residence
A39: Downtown Client Office | B39: Dubai Head Office | C39: Office
A40: Abu Dhabi Site Office | B40: Abu Dhabi Site | C40: Office
A41: Yas Island Hotel | B41: Abu Dhabi Site | C41: Hotel
A42: Mussafah Depot | B42: Abu Dhabi Site | C42: Warehouse
A43: Zayed International Airport | B43: Abu Dhabi Site | C43: Airport
A45: Vehicle types
...

Sheet Bug Log
A1: Bug ID | B1: Date found | C1: Test case ID | D1: Module | E1: Summary | F1: Steps to reproduce | G1: Expected | H1: Actual | I1: Severity | J1: Status | K1: Evidence (screenshot / console) | L1: Fixed in / retest date
A2: EXAMPLE | B2: 12-Oct-2026 | C2: DRV-014 | D2: 06 Driver Dashboard | E2: Wrong notice when no vehicle is free | F2: 1. Fresh seed. 2. Open Driver.aspx as Rashid. 3. Click Accept on FB-0002. | G2: Notice says no vehicle is available. | H2: Notice also says another driver accepted the trip first. | I2: Medium | J2: Open | K2: Screenshot drv-014.png
A61: Row 2 is an example showing the expected format. Delete it or leave it; start your own entries from row 3.
